Workbook
Name uHead: #REF!
Name uHead: #REF!

Sheet YuHui
A1: 買進日期 | B1: 種類 | C1: 股票代號 | D1: 股票名稱 | E1: 股數 | F1: 買進價 | G1: 成交金額 | H1: 手續費 | I1: 賣出日期 | J1: 賣出價 | K1: 成交金額 | L1: 手續費 | M1: 交易稅 | N1: 證所稅 | O1: 參考現值 | P1: 已實現損益 | Q1: 未實現損益 | R1: 除息 | S1: 手續費 | T1: 健保補充保費 | U1: 實質扣抵稅率 | V1: 扣抵稅率 | W1: 所得稅率 | X1: 投資報酬率 | Y1: 今日股價 | Z1: 漲跌 | AB1: 分類
A2: 45707 | C2: 3078 | D2: 僑威 | E2: 1000 | F2: 87.9 | G2: =E2*F2 -> 87900 | H2: 75 | I2: 45709 | J2: 85.3 | K2: =E2*J2 -> 85300 | L2: 72 | M2: 255 | N2: 0 | O2: =IF(I2="",E2*Y2,0) -> 0 | P2: =IF(I2="",R2-H2,(K2-H2-SUM(L2:N2)+R2-S2-T2)-G2)+(ROUND(R2*V2,0)-ROUND(R2*(1+V2),0)*W2) -> -3012 | Q2: =IF(I2="",(O2-G2-(O2*0.1425%*0.65)-(O2*0.3%)-S2-T2),0) -> 0 | S2: 10 | U2: =(V2*50%)/(1+50%*V2) -> 0 | W2: 0.11 | X2: =(P2+Q2)/G2 -> -0.034266212 | Y2: =VLOOKUP(C2,每日行情!A:D,4,FALSE) -> 47.3 | Z2: =VLOOKUP(C2,每日行情!A:E,5,FALSE) -> -0.1 | AA2: =IF(I2="",((TODAY()-A2)*G2)/365.24,((I2-A2)*G2)/365.24) -> 481.32735 | AB2: 台股
A3: 45698 | C3: 6245 | D3: 立端 | E3: 1000 | F3: 113.5 | G3: =E3*F3 -> 113500 | H3: 97 | I3: 45713 | J3: 115.5 | K3: =E3*J3 -> 115500 | L3: 98 | M3: 346 | N3: 0 | O3: =IF(I3="",E3*Y3,0) -> 0 | P3: =IF(I3="",R3-H3,(K3-H3-SUM(L3:N3)+R3-S3-T3)-G3)+(ROUND(R3*V3,0)-ROUND(R3*(1+V3),0)*W3) -> 1449 | Q3: =IF(I3="",(O3-G3-(O3*0.1425%*0.65)-(O3*0.3%)-S3-T3),0) -> 0 | S3: 10 | U3: =(V3*50%)/(1+50%*V3) -> 0 | W3: 0.11 | X3: =(P3+Q3)/G3 -> 0.01276652 | Y3: =VLOOKUP(C3,每日行情!A:D,4,FALSE) -> 89.3 | Z3: =VLOOKUP(C3,每日行情!A:E,5,FALSE) -> 1.6 | AA3: =IF(I3="",((TODAY()-A3)*G3)/365.24,((I3-A3)*G3)/365.24) -> 4661.3186 | AB3: 台股
A4: 45699 | C4: 6596 | D4: 寬宏藝術 | E4: 1000 | F4: 92.5 | G4: =E4*F4 -> 92500 | H4: 79 | I4: 45714 | J4: 91.9 | K4: =E4*J4 -> 91900 | L4: 78 | M4: 275 | N4: 0 | O4: =IF(I4="",E4*Y4,0) -> 0 | P4: =IF(I4="",R4-H4,(K4-H4-SUM(L4:N4)+R4-S4-T4)-G4)+(ROUND(R4*V4,0)-ROUND(R4*(1+V4),0)*W4) -> -1042 | Q4: =IF(I4="",(O4-G4-(O4*0.1425%*0.65)-(O4*0.3%)-S4-T4),0) -> 0 | S4: 10 | U4: =(V4*50%)/(1+50%*V4) -> 0 | W4: 0.11 | X4: =(P4+Q4)/G4 -> -0.011264865 | Y4: =VLOOKUP(C4,每日行情!A:D,4,FALSE) -> 96.1 | Z4: =VLOOKUP(C4,每日行情!A:E,5,FALSE) -> 0.8 | AA4: =IF(I4="",((TODAY()-A4)*G4)/365.24,((I4-A4)*G4)/365.24) -> 3798.872 | AB4: 台股
A5: 45702 | C5: 2301 | D5: 光寶科 | E5: 1000 | F5: 110.5 | G5: =E5*F5 -> 110500 | H5: 94 | I5: 45715 | J5: 110 | K5: =E5*J5 -> 110000 | L5: 94 | M5: 330 | N5: 0 | O5: =IF(I5="",E5*Y5,0) -> 0 | P5: =IF(I5="",R5-H5,(K5-H5-SUM(L5:N5)+R5-S5-T5)-G5)+(ROUND(R5*V5,0)-ROUND(R5*(1+V5),0)*W5) -> -1028 | Q5: =IF(I5="",(O5-G5-(O5*0.1425%*0.65)-(O5*0.3%)-S5-T5),0) -> 0 | S5: 10 | U5: =(V5*50%)/(1+50%*V5) -> 0 | W5: 0.11 | X5: =(P5+Q5)/G5 -> -0.0093031674 | Y5: =VLOOKUP(C5,每日行情!A:D,4,FALSE) -> 264.5 | Z5: =VLOOKUP(C5,每日行情!A:E,5,FALSE) -> -3.5 | AA5: =IF(I5="",((TODAY()-A5)*G5)/365.24,((I5-A5)*G5)/365.24) -> 3933.0303 | AB5: 台股
A6: 45706 | C6: 2883 | D6: 凱基金 | E6: 1000 | F6: 17.9 | G6: =E6*F6 -> 17900 | H6: 20 | I6: 45715 | J6: 18.15 | K6: =E6*J6 -> 18150 | L6: 20 | M6: 54 | N6: 0 | O6: =IF(I6="",E6*Y6,0) -> 0 | P6: =IF(I6="",R6-H6,(K6-H6-SUM(L6:N6)+R6-S6-T6)-G6)+(ROUND(R6*V6,0)-ROUND(R6*(1+V6),0)*W6) -> 146 | Q6: =IF(I6="",(O6-G6-(O6*0.1425%*0.65)-(O6*0.3%)-S6-T6),0) -> 0 | S6: 10 | U6: =(V6*50%)/(1+50%*V6) -> 0 | W6: 0.11 | X6: =(P6+Q6)/G6 -> 0.0081564246 | Y6: =VLOOKUP(C6,每日行情!A:D,4,FALSE) -> 39.1 | Z6: =VLOOKUP(C6,每日行情!A:E,5,FALSE) -> 0.7 | AA6: =IF(I6="",((TODAY()-A6)*G6)/365.24,((I6-A6)*G6)/365.24) -> 441.07984 | AB6: 台股
A7: 45702 | C7: 2884 | D7: 玉山金 | E7: 1000 | F7: 29.1 | G7: =E7*F7 -> 29100 | H7: 24 | I7: 45715 | J7: 29.5 | K7: =E7*J7 -> 29500 | L7: 25 | M7: 88 | N7: 0 | O7: =IF(I7="",E7*Y7,0) -> 0 | P7: =IF(I7="",R7-H7,(K7-H7-SUM(L7:N7)+R7-S7-T7)-G7)+(ROUND(R7*V7,0)-ROUND(R7*(1+V7),0)*W7) -> 253 | Q7: =IF(I7="",(O7-G7-(O7*0.1425%*0.65)-(O7*0.3%)-S7-T7),0) -> 0 | S7: 10 | U7: =(V7*50%)/(1+50%*V7) -> 0 | W7: 0.11 | X7: =(P7+Q7)/G7 -> 0.0086941581 | Y7: =VLOOKUP(C7,每日行情!A:D,4,FALSE) -> 49.15 | Z7: =VLOOKUP(C7,每日行情!A:E,5,FALSE) -> 0.35 | AA7: =IF(I7="",((TODAY()-A7)*G7)/365.24,((I7-A7)*G7)/365.24) -> 1035.7573 | AB7: 台股
A8: 45698 | C8: 6206 | D8: 飛捷 | E8: 1000 | F8: 118.5 | G8: =E8*F8 -> 118500 | H8: 101 | I8: 45715 | J8: 162.5 | K8: =E8*J8 -> 162500 | L8: 138 | M8: 487 | N8: 0 | O8: =IF(I8="",E8*Y8,0) -> 0 | P8: =IF(I8="",R8-H8,(K8-H8-SUM(L8:N8)+R8-S8-T8)-G8)+(ROUND(R8*V8,0)-ROUND(R8*(1+V8),0)*W8) -> 43264 | Q8: =IF(I8="",(O8-G8-(O8*0.1425%*0.65)-(O8*0.3%)-S8-T8),0) -> 0 | S8: 10 | U8: =(V8*50%)/(1+50%*V8) -> 0 | W8: 0.11 | X8: =(P8+Q8)/G8 -> 0.36509705 | Y8: =VLOOKUP(C8,每日行情!A:D,4,FALSE) -> 36.56 | Z8: =VLOOKUP(C8,每日行情!A:E,5,FALSE) -> 0.4 | AA8: =IF(I8="",((TODAY()-A8)*G8)/365.24,((I8-A8)*G8)/365.24) -> 5515.5514 | AB8: 台股
A9: 45702 | C9: 1605 | D9: 華新 | E9: 1000 | F9: 26.65 | G9: =E9*F9 -> 26650 | H9: 23 | I9: 45720 | J9: 27.6 | K9: =E9*J9 -> 27600 | L9: 23 | M9: 82 | N9: 0 | O9: =IF(I9="",E9*Y9,0) -> 0 | P9: =IF(I9="",R9-H9,(K9-H9-SUM(L9:N9)+R9-S9-T9)-G9)+(ROUND(R9*V9,0)-ROUND(R9*(1+V9),0)*W9) -> 812 | Q9: =IF(I9="",(O9-G9-(O9*0.1425%*0.65)-(O9*0.3%)-S9-T9),0) -> 0 | S9: 10 | U9: =(V9*50%)/(1+50%*V9) -> 0 | W9: 0.11 | X9: =(P9+Q9)/G9 -> 0.030469043 | Y9: =VLOOKUP(C9,每日行情!A:D,4,FALSE) -> 38.5 | Z9: =VLOOKUP(C9,每日行情!A:E,5,FALSE) -> 0.8 | AA9: =IF(I9="",((TODAY()-A9)*G9)/365.24,((I9-A9)*G9)/365.24) -> 1313.383 | AB9: 台股
A10: 45702 | C10: 1605 | D10: 華新 | E10: 1000 | F10: 26.65 | G10: =E10*F10 -> 26650 | H10: 22 | I10: 45721 | J10: 27.75 | K10: =E10*J10 -> 27750 | L10: 23 | M10: 83 | N10: 0 | O10: =IF(I10="",E10*Y10,0) -> 0 | P10: =IF(I10="",R10-H10,(K10-H10-SUM(L10:N10)+R10-S10-T10)-G10)+(ROUND(R10*V10,0)-ROUND(R10*(1+V10),0)*W10) -> 962 | Q10: =IF(I10="",(O10-G10-(O10*0.1425%*0.65)-(O10*0.3%)-S10-T10),0) -> 0 | S10: 10 | U10: =(V10*50%)/(1+50%*V10) -> 0 | W10: 0.11 | X10: =(P10+Q10)/G10 -> 0.036097561 | Y10: =VLOOKUP(C10,每日行情!A:D,4,FALSE) -> 38.5 | Z10: =VLOOKUP(C10,每日行情!A:E,5,FALSE) -> 0.8 | AA10: =IF(I10="",((TODAY()-A10)*G10)/365.24,((I10-A10)*G10)/365.24) -> 1386.3487 | AB10: 台股
A11: 45709 | C11: 2357 | D11: 華碩 | E11: 100 | F11: 700 | G11: =E11*F11 -> 70000 | H11: 59 | I11: 45727 | J11: 646 | K11: =E11*J11 -> 64600 | L11: 55 | M11: 193 | N11: 0 | O11: =IF(I11="",E11*Y11,0) -> 0 | P11: =IF(I11="",R11-H11,(K11-H11-SUM(L11:N11)+R11-S11-T11)-G11)+(ROUND(R11*V11,0)-ROUND(R11*(1+V11),0)*W11) -> -5717 | Q11: =IF(I11="",(O11-G11-(O11*0.1425%*0.65)-(O11*0.3%)-S11-T11),0) -> 0 | S11: 10 | U11: =(V11*50%)/(1+50%*V11) -> 0 | W11: 0.11 | X11: =(P11+Q11)/G11 -> -0.081671429 | Y11: =VLOOKUP(C11,每日行情!A:D,4,FALSE) -> 994 | Z11: =VLOOKUP(C11,每日行情!A:E,5,FALSE) -> 19 | AA11: =IF(I11="",((TODAY()-A11)*G11)/365.24,((I11-A11)*G11)/365.24) -> 3449.7864 | AB11: 台股
A12: 45713 | C12: 1519 | D12: 華城 | E12: 1000 | F12: 654 | G12: =E12*F12 -> 654000 | H12: 559 | I12: 45727 | J12: 590 | K12: =E12*J12 -> 590000 | L12: 504 | M12: 1770 | N12: 0 | O12: =IF(I12="",E12*Y12,0) -> 0 | P12: =IF(I12="",R12-H12,(K12-H12-SUM(L12:N12)+R12-S12-T12)-G12)+(ROUND(R12*V12,0)-ROUND(R12*(1+V12),0)*W12) -> -66843 | Q12: =IF(I12="",(O12-G12-(O12*0.1425%*0.65)-(O12*0.3%)-S12-T12),0) -> 0 | S12: 10 | U12: =(V12*50%)/(1+50%*V12) -> 0 | W12: 0.11 | X12: =(P12+Q12)/G12 -> -0.10220642 | Y12: =VLOOKUP(C12,每日行情!A:D,4,FALSE) -> 656 | Z12: =VLOOKUP(C12,每日行情!A:E,5,FALSE) -> 7 | AA12: =IF(I12="",((TODAY()-A12)*G12)/365.24,((I12-A12)*G12)/365.24) -> 25068.448 | AB12: 台股
A13: 45723 | C13: 6257 | D13: 矽格 | E13: 1000 | F13: 81.7 | G13: =E13*F13 -> 81700 | H13: 69 | I13: 45727 | J13: 75.5 | K13: =E13*J13 -> 75500 | L13: 64 | M13: 226 | N13: 0 | O13: =IF(I13="",E13*Y13,0) -> 0 | P13: =IF(I13="",R13-H13,(K13-H13-SUM(L13:N13)+R13-S13-T13)-G13)+(ROUND(R13*V13,0)-ROUND(R13*(1+V13),0)*W13) -> -6569 | Q13: =IF(I13="",(O13-G13-(O13*0.1425%*0.65)-(O13*0.3%)-S13-T13),0) -> 0 | S13: 10 | U13: =(V13*50%)/(1+50%*V13) -> 0 | W13: 0.11 | X13: =(P13+Q13)/G13 -> -0.080403917 | Y13: =VLOOKUP(C13,每日行情!A:D,4,FALSE) -> 252 | Z13: =VLOOKUP(C13,每日行情!A:E,5,FALSE) -> -6 | AA13: =IF(I13="",((TODAY()-A13)*G13)/365.24,((I13-A13)*G13)/365.24) -> 894.75413 | AB13: 台股
A14: 45723 | C14: 2027 | D14: =VLOOKUP(C14,每日行情!A:B,2,FALSE) -> 大成鋼 | E14: 1000 | F14: 49.2 | G14: =E14*F14 -> 49200 | H14: 42 | I14: 45728 | J14: 48.85 | K14: =E14*J14 -> 48850 | L14: 41 | M14: 146 | N14: 0 | O14: =IF(I14="",E14*Y14,0) -> 0 | P14: =IF(I14="",R14-H14,(K14-H14-SUM(L14:N14)+R14-S14-T14)-G14)+(ROUND(R14*V14,0)-ROUND(R14*(1+V14),0)*W14) -> -589 | Q14: =IF(I14="",(O14-G14-(O14*0.1425%*0.65)-(O14*0.3%)-S14-T14),0) -> 0 | S14: 10 | U14: =(V14*50%)/(1+50%*V14) -> 0 | W14: 0.11 | X14: =(P14+Q14)/G14 -> -0.011971545 | Y14: =VLOOKUP(C14,每日行情!A:D,4,FALSE) -> 50.9 | Z14: =VLOOKUP(C14,每日行情!A:E,5,FALSE) -> 1.6 | AA14: =IF(I14="",((TODAY()-A14)*G14)/365.24,((I14-A14)*G14)/365.24) -> 673.52973 | AB14: 台股
A15: 45702 | C15: 2606 | D15: =VLOOKUP(C15,每日行情!A:B,2,FALSE) -> 裕民 | E15: 1000 | F15: 69.3 | G15: =E15*F15 -> 69300 | H15: 59 | I15: 45728 | J15: 70.6 | K15: =E15*J15 -> 70600 | L15: 60 | M15: 211 | N15: 0 | O15: =IF(I15="",E15*Y15,0) -> 0 | P15: =IF(I15="",R15-H15,(K15-H15-SUM(L15:N15)+R15-S15-T15)-G15)+(ROUND(R15*V15,0)-ROUND(R15*(1+V15),0)*W15) -> 960 | Q15: =IF(I15="",(O15-G15-(O15*0.1425%*0.65)-(O15*0.3%)-S15-T15),0) -> 0 | S15: 10 | U15: =(V15*50%)/(1+50%*V15) -> 0 | W15: 0.11 | X15: =(P15+Q15)/G15 -> 0.013852814 | Y15: =VLOOKUP(C15,每日行情!A:D,4,FALSE) -> 75.2 | Z15: =VLOOKUP(C15,每日行情!A:E,5,FALSE) -> -0.8 | AA15: =IF(I15="",((TODAY()-A15)*G15)/365.24,((I15-A15)*G15)/365.24) -> 4933.1946 | AB15: 台股
A16: 45729 | C16: 3211 | D16: =VLOOKUP(C16,每日行情!A:B,2,FALSE) -> 順達 | E16: 1000 | F16: 210.5 | G16: =E16*F16 -> 210500 | H16: 179 | I16: 45729 | J16: 213.5 | K16: =E16*J16 -> 213500 | L16: 182 | M16: 320 | N16: 0 | O16: =IF(I16="",E16*Y16,0) -> 0 | P16: =IF(I16="",R16-H16,(K16-H16-SUM(L16:N16)+R16-S16-T16)-G16)+(ROUND(R16*V16,0)-ROUND(R16*(1+V16),0)*W16) -> 2309 | Q16: =IF(I16="",(O16-G16-(O16*0.1425%*0.65)-(O16*0.3%)-S16-T16),0) -> 0 | S16: 10 | U16: =(V16*50%)/(1+50%*V16) -> 0 | W16: 0.11 | X16: =(P16+Q16)/G16 -> 0.010969121 | Y16: =VLOOKUP(C16,每日行情!A:D,4,FALSE) -> 346 | Z16: =VLOOKUP(C16,每日行情!A:E,5,FALSE) -> -3 | AA16: =IF(I16="",((TODAY()-A16)*G16)/365.24,((I16-A16)*G16)/365.24) -> 0 | AB16: 台股
A17: 45721 | C17: 6196 | D17: =VLOOKUP(C17,每日行情!A:B,2,FALSE) -> 帆宣 | E17: 1000 | F17: 172 | G17: =E17*F17 -> 172000 | H17: 147 | I17: 45729 | J17: 162 | K17: =E17*J17 -> 162000 | L17: 138 | M17: 486 | N17: 0 | O17: =IF(I17="",E17*Y17,0) -> 0 | P17: =IF(I17="",R17-H17,(K17-H17-SUM(L17:N17)+R17-S17-T17)-G17)+(ROUND(R17*V17,0)-ROUND(R17*(1+V17),0)*W17) -> -10781 | Q17: =IF(I17="",(O17-G17-(O17*0.1425%*0.65)-(O17*0.3%)-S17-T17),0) -> 0 | S17: 10 | U17: =(V17*50%)/(1+50%*V17) -> 0 | W17: 0.11 | X17: =(P17+Q17)/G17 -> -0.062680233 | Y17: =VLOOKUP(C17,每日行情!A:D,4,FALSE) -> 609 | Z17: =VLOOKUP(C17,每日行情!A:E,5,FALSE) -> -4 | AA17: =IF(I17="",((TODAY()-A17)*G17)/365.24,((I17-A17)*G17)/365.24) -> 3767.3858 | AB17: 台股
A18: 45728 | C18: 4931 | D18: =VLOOKUP(C18,每日行情!A:B,2,FALSE) -> 新盛力 | E18: 1000 | F18: 86.8 | G18: =E18*F18 -> 86800 | H18: 74 | I18: 45730 | J18: 87.6 | K18: =E18*J18 -> 87600 | L18: 74 | M18: 262 | N18: 0 | O18: =IF(I18="",E18*Y18,0) -> 0 | P18: =IF(I18="",R18-H18,(K18-H18-SUM(L18:N18)+R18-S18-T18)-G18)+(ROUND(R18*V18,0)-ROUND(R18*(1+V18),0)*W18) -> 380 | Q18: =IF(I18="",(O18-G18-(O18*0.1425%*0.65)-(O18*0.3%)-S18-T18),0) -> 0 | S18: 10 | U18: =(V18*50%)/(1+50%*V18) -> 0 | W18: 0.11 | X18: =(P18+Q18)/G18 -> 0.0043778802 | Y18: =VLOOKUP(C18,每日行情!A:D,4,FALSE) -> 217 | Z18: =VLOOKUP(C18,每日行情!A:E,5,FALSE) -> 4 | AA18: =IF(I18="",((TODAY()-A18)*G18)/365.24,((I18-A18)*G18)/365.24) -> 475.30391 | AB18: 台股
A19: 45730 | C19: 3163 | D19: =VLOOKUP(C19,每日行情!A:B,2,FALSE) -> 波若威 | E19: 1000 | F19: 170 | G19: =E19*F19 -> 170000 | H19: 145 | I19: 45730 | J19: 173 | K19: =E19*J19 -> 173000 | L19: 147 | M19: 259 | N19: 0 | O19: =IF(I19="",E19*Y19,0) -> 0 | P19: =IF(I19="",R19-H19,(K19-H19-SUM(L19:N19)+R19-S19-T19)-G19)+(ROUND(R19*V19,0)-ROUND(R19*(1+V19),0)*W19) -> 2439 | Q19: =IF(I19="",(O19-G19-(O19*0.1425%*0.65)-(O19*0.3%)-S19-T19),0) -> 0 | S19: 10 | U19: =(V19*50%)/(1+50%*V19) -> 0 | W19: 0.11 | X19: =(P19+Q19)/G19 -> 0.014347059 | Y19: =VLOOKUP(C19,每日行情!A:D,4,FALSE) -> 589 | Z19: =VLOOKUP(C19,每日行情!A:E,5,FALSE) -> -15 | AA19: =IF(I19="",((TODAY()-A19)*G19)/365.24,((I19-A19)*G19)/365.24) -> 0 | AB19: 台股
A20: 45736 | C20: 2634 | D20: =VLOOKUP(C20,每日行情!A:B,2,FALSE) -> 漢翔 | E20: 1000 | F20: 52.9 | G20: =E20*F20 -> 52900 | H20: 45 | I20: 45736 | J20: 51.1 | K20: =E20*J20 -> 51100 | L20: 43 | M20: 76 | N20: 0 | O20: =IF(I20="",E20*Y20,0) -> 0 | P20: =IF(I20="",R20-H20,(K20-H20-SUM(L20:N20)+R20-S20-T20)-G20)+(ROUND(R20*V20,0)-ROUND(R20*(1+V20),0)*W20) -> -1974 | Q20: =IF(I20="",(O20-G20-(O20*0.1425%*0.65)-(O20*0.3%)-S20-T20),0) -> 0 | S20: 10 | U20: =(V20*50%)/(1+50%*V20) -> 0 | W20: 0.11 | X20: =(P20+Q20)/G20 -> -0.03731569 | Y20: =VLOOKUP(C20,每日行情!A:D,4,FALSE) -> 62.1 | Z20: =VLOOKUP(C20,每日行情!A:E,5,FALSE) -> 1.4 | AA20: =IF(I20="",((TODAY()-A20)*G20)/365.24,((I20-A20)*G20)/365.24) -> 0 | AB20: 台股
A21: 45714 | C21: 8299 | D21: =VLOOKUP(C21,每日行情!A:B,2,FALSE) -> 群聯 | E21: 1000 | F21: 564 | G21: =E21*F21 -> 564000 | H21: 482 | I21: 45741 | J21: 573 | K21: =E21*J21 -> 573000 | L21: 489 | M21: 1719 | N21: 0 | O21: =IF(I21="",E21*Y21,0) -> 0 | P21: =IF(I21="",R21-H21,(K21-H21-SUM(L21:N21)+R21-S21-T21)-G21)+(ROUND(R21*V21,0)-ROUND(R21*(1+V21),0)*W21) -> 6300 | Q21: =IF(I21="",(O21-G21-(O21*0.1425%*0.65)-(O21*0.3%)-S21-T21),0) -> 0 | S21: 10 | U21: =(V21*50%)/(1+50%*V21) -> 0 | W21: 0.11 | X21: =(P21+Q21)/G21 -> 0.011170213 | Y21: =VLOOKUP(C21,每日行情!A:D,4,FALSE) -> 1890 | Z21: =VLOOKUP(C21,每日行情!A:E,5,FALSE) -> 60 | AA21: =IF(I21="",((TODAY()-A21)*G21)/365.24,((I21-A21)*G21)/365.24) -> 41693.133 | AB21: 台股
A22: 45737 | C22: 1319 | D22: =VLOOKUP(C22,每日行情!A:B,2,FALSE) -> 東陽 | E22: 1000 | F22: 138 | G22: =E22*F22 -> 138000 | H22: 117 | I22: 45742 | J22: 133 | K22: =E22*J22 -> 133000 | L22: 113 | M22: 399 | N22: 0 | O22: =IF(I22="",E22*Y22,0) -> 0 | P22: =IF(I22="",R22-H22,(K22-H22-SUM(L22:N22)+R22-S22-T22)-G22)+(ROUND(R22*V22,0)-ROUND(R22*(1+V22),0)*W22) -> -5639 | Q22: =IF(I22="",(O22-G22-(O22*0.1425%*0.65)-(O22*0.3%)-S22-T22),0) -> 0 | S22: 10 | U22: =(V22*50%)/(1+50%*V22) -> 0 | W22: 0.11 | X22: =(P22+Q22)/G22 -> -0.040862319 | Y22: =VLOOKUP(C22,每日行情!A:D,4,FALSE) -> 83.5 | Z22: =VLOOKUP(C22,每日行情!A:E,5,FALSE) -> 0.2 | AA22: =IF(I22="",((TODAY()-A22)*G22)/365.24,((I22-A22)*G22)/365.24) -> 1889.1688 | AB22: 台股
A23: 45735 | C23: 2609 | D23: =VLOOKUP(C23,每日行情!A:B,2,FALSE) -> 陽明 | E23: 1000 | F23: 77.2 | G23: =E23*F23 -> 77200 | H23: 45 | I23: 45743 | J23: 76.2 | K23: =E23*J23 -> 76200 | L23: 65 | M23: 228 | N23: 0 | O23: =IF(I23="",E23*Y23,0) -> 0 | P23: =IF(I23="",R23-H23,(K23-H23-SUM(L23:N23)+R23-S23-T23)-G23)+(ROUND(R23*V23,0)-ROUND(R23*(1+V23),0)*W23) -> -1348 | Q23: =IF(I23="",(O23-G23-(O23*0.1425%*0.65)-(O23*0.3%)-S23-T23),0) -> 0 | S23: 10 | U23: =(V23*50%)/(1+50%*V23) -> 0 | W23: 0.11 | X23: =(P23+Q23)/G23 -> -0.01746114 | Y23: =VLOOKUP(C23,每日行情!A:D,4,FALSE) -> 64.7 | Z23: =VLOOKUP(C23,每日行情!A:E,5,FALSE) -> 1.4 | AA23: =IF(I23="",((TODAY()-A23)*G23)/365.24,((I23-A23)*G23)/365.24) -> 1690.9429 | AB23: 台股
A24: 45737 | C24: 2634 | D24: =VLOOKUP(C24,每日行情!A:B,2,FALSE) -> 漢翔 | E24: 1000 | F24: 51.7 | G24: =E24*F24 -> 51700 | H24: 44 | I24: 45743 | J24: 52.5 | K24: =E24*J24 -> 52500 | L24: 44 | M24: 157 | N24: 0 | O24: =IF(I24="",E24*Y24,0) -> 0 | P24: =IF(I24="",R24-H24,(K24-H24-SUM(L24:N24)+R24-S24-T24)-G24)+(ROUND(R24*V24,0)-ROUND(R24*(1+V24),0)*W24) -> 545 | Q24: =IF(I24="",(O24-G24-(O24*0.1425%*0.65)-(O24*0.3%)-S24-T24),0) -> 0 | S24: 10 | U24: =(V24*50%)/(1+50%*V24) -> 0 | W24: 0.11 | X24: =(P24+Q24)/G24 -> 0.010541586 | Y24: =VLOOKUP(C24,每日行情!A:D,4,FALSE) -> 62.1 | Z24: =VLOOKUP(C24,每日行情!A:E,5,FALSE) -> 1.4 | AA24: =IF(I24="",((TODAY()-A24)*G24)/365.24,((I24-A24)*G24)/365.24) -> 849.30457 | AB24: 台股
A25: 45740 | C25: 3035 | D25: =VLOOKUP(C25,每日行情!A:B,2,FALSE) -> 智原 | E25: 1000 | F25: 249 | G25: =E25*F25 -> 249000 | H25: 212 | I25: 45743 | J25: 242 | K25: =E25*J25 -> 242000 | L25: 206 | M25: 726 | N25: 0 | O25: =IF(I25="",E25*Y25,0) -> 0 | P25: =IF(I25="",R25-H25,(K25-H25-SUM(L25:N25)+R25-S25-T25)-G25)+(ROUND(R25*V25,0)-ROUND(R25*(1+V25),0)*W25) -> -8154 | Q25: =IF(I25="",(O25-G25-(O25*0.1425%*0.65)-(O25*0.3%)-S25-T25),0) -> 0 | S25: 10 | U25: =(V25*50%)/(1+50%*V25) -> 0 | W25: 0.11 | X25: =(P25+Q25)/G25 -> -0.032746988 | Y25: =VLOOKUP(C25,每日行情!A:D,4,FALSE) -> 197.5 | Z25: =VLOOKUP(C25,每日行情!A:E,5,FALSE) -> 0 | AA25: =IF(I25="",((TODAY()-A25)*G25)/365.24,((I25-A25)*G25)/365.24) -> 2045.2305 | AB25: 台股
A26: 45740 | C26: 5534 | D26: =VLOOKUP(C26,每日行情!A:B,2,FALSE) -> 長虹 | E26: 1000 | F26: 108 | G26: =E26*F26 -> 108000 | H26: 92 | I26: 45743 | J26: 105.5 | K26: =E26*J26 -> 105500 | L26: 90 | M26: 316 | N26: 0 | O26: =IF(I26="",E26*Y26,0) -> 0 | P26: =IF(I26="",R26-H26,(K26-H26-SUM(L26:N26)+R26-S26-T26)-G26)+(ROUND(R26*V26,0)-ROUND(R26*(1+V26),0)*W26) -> -3008 | Q26: =IF(I26="",(O26-G26-(O26*0.1425%*0.65)-(O26*0.3%)-S26-T26),0) -> 0 | S26: 10 | U26: =(V26*50%)/(1+50%*V26) -> 0 | W26: 0.11 | X26: =(P26+Q26)/G26 -> -0.027851852 | Y26: =VLOOKUP(C26,每日行情!A:D,4,FALSE) -> 70.3 | Z26: =VLOOKUP(C26,每日行情!A:E,5,FALSE) -> -0.5 | AA26: =IF(I26="",((TODAY()-A26)*G26)/365.24,((I26-A26)*G26)/365.24) -> 887.08794 | AB26: 台股
A27: 45910 | C27: 1711 | D27: =VLOOKUP(C27,每日行情!A:B,2,FALSE) -> 永光 | E27: 3000 | F27: 20.3 | G27: =E27*F27 -> 60900 | H27: 52 | I27: 45924 | J27: 19.65 | K27: =E27*J27 -> 58950 | L27: 50 | M27: 176 | N27: 0 | O27: =IF(I27="",E27*Y27,0) -> 0 | P27: =IF(I27="",R27-H27,(K27-H27-SUM(L27:N27)+R27-S27-T27)-G27)+(ROUND(R27*V27,0)-ROUND(R27*(1+V27),0)*W27) -> -2228 | Q27: =IF(I27="",(O27-G27-(O27*0.1425%*0.65)-(O27*0.3%)-S27-T27),0) -> 0 | U27: =(V27*50%)/(1+50%*V27) -> 0 | W27: 0.11 | X27: =(P27+Q27)/G27 -> -0.036584565 | Y27: =VLOOKUP(C27,每日行情!A:D,4,FALSE) -> 44.45 | Z27: =VLOOKUP(C27,每日行情!A:E,5,FALSE) -> 1.35 | AA27: =IF(I27="",((TODAY()-A27)*G27)/365.24,((I27-A27)*G27)/365.24) -> 2334.3555 | AB27: 台股
A28: 45917 | C28: 3006 | D28: =VLOOKUP(C28,每日行情!A:B,2,FALSE) -> 晶豪科 | E28: 1000 | F28: 65.4 | G28: =E28*F28 -> 65400 | H28: 55 | I28: 45925 | J28: 72.5 | K28: =E28*J28 -> 72500 | L28: 61 | M28: 217 | N28: 0 | O28: =IF(I28="",E28*Y28,0) -> 0 | P28: =IF(I28="",R28-H28,(K28-H28-SUM(L28:N28)+R28-S28-T28)-G28)+(ROUND(R28*V28,0)-ROUND(R28*(1+V28),0)*W28) -> 6767 | Q28: =IF(I28="",(O28-G28-(O28*0.1425%*0.65)-(O28*0.3%)-S28-T28),0) -> 0 | U28: =(V28*50%)/(1+50%*V28) -> 0 | W28: 0.11 | X28: =(P28+Q28)/G28 -> 0.10347095 | Y28: =VLOOKUP(C28,每日行情!A:D,4,FALSE) -> 244.5 | Z28: =VLOOKUP(C28,每日行情!A:E,5,FALSE) -> 15.5 | AA28: =IF(I28="",((TODAY()-A28)*G28)/365.24,((I28-A28)*G28)/365.24) -> 1432.4828 | AB28: 台股
A29: 45917 | C29: 3042 | D29: =VLOOKUP(C29,每日行情!A:B,2,FALSE) -> 晶技 | E29: 1000 | F29: 92.8 | G29: =E29*F29 -> 92800 | H29: 79 | I29: 45925 | J29: 91.4 | K29: =E29*J29 -> 91400 | L29: 78 | M29: 274 | N29: 0 | O29: =IF(I29="",E29*Y29,0) -> 0 | P29: =IF(I29="",R29-H29,(K29-H29-SUM(L29:N29)+R29-S29-T29)-G29)+(ROUND(R29*V29,0)-ROUND(R29*(1+V29),0)*W29) -> -1831 | Q29: =IF(I29="",(O29-G29-(O29*0.1425%*0.65)-(O29*0.3%)-S29-T29),0) -> 0 | U29: =(V29*50%)/(1+50%*V29) -> 0 | W29: 0.11 | X29: =(P29+Q29)/G29 -> -0.019730603 | Y29: =VLOOKUP(C29,每日行情!A:D,4,FALSE) -> 188 | Z29: =VLOOKUP(C29,每日行情!A:E,5,FALSE) -> -1.5 | AA29: =IF(I29="",((TODAY()-A29)*G29)/365.24,((I29-A29)*G29)/365.24) -> 2032.6361 | AB29: 台股
A30: 45917 | C30: 3532 | D30: =VLOOKUP(C30,每日行情!A:B,2,FALSE) -> 台勝科 | E30: 1000 | F30: 95 | G30: =E30*F30 -> 95000 | H30: 81 | I30: 45925 | J30: 106.5 | K30: =E30*J30 -> 106500 | L30: 91 | M30: 319 | N30: 0 | O30: =IF(I30="",E30*Y30,0) -> 0 | P30: =IF(I30="",R30-H30,(K30-H30-SUM(L30:N30)+R30-S30-T30)-G30)+(ROUND(R30*V30,0)-ROUND(R30*(1+V30),0)*W30) -> 11009 | Q30: =IF(I30="",(O30-G30-(O30*0.1425%*0.65)-(O30*0.3%)-S30-T30),0) -> 0 | U30: =(V30*50%)/(1+50%*V30) -> 0 | W30: 0.11 | X30: =(P30+Q30)/G30 -> 0.11588421 | Y30: =VLOOKUP(C30,每日行情!A:D,4,FALSE) -> 417.5 | Z30: =VLOOKUP(C30,每日行情!A:E,5,FALSE) -> 17.5 | AA30: =IF(I30="",((TODAY()-A30)*G30)/365.24,((I30-A30)*G30)/365.24) -> 2080.8236 | AB30: 台股
A31: 45925 | C31: 2324 | D31: =VLOOKUP(C31,每日行情!A:B,2,FALSE) -> 仁寶 | E31: 2000 | F31: 37.1 | G31: =E31*F31 -> 74200 | H31: 63 | I31: 45930 | J31: 32.4 | K31: =E31*J31 -> 64800 | L31: 55 | M31: 194 | N31: 0 | O31: =IF(I31="",E31*Y31,0) -> 0 | P31: =IF(I31="",R31-H31,(K31-H31-SUM(L31:N31)+R31-S31-T31)-G31)+(ROUND(R31*V31,0)-ROUND(R31*(1+V31),0)*W31) -> -9712 | Q31: =IF(I31="",(O31-G31-(O31*0.1425%*0.65)-(O31*0.3%)-S31-T31),0) -> 0 | U31: =(V31*50%)/(1+50%*V31) -> 0 | W31: 0.11 | X31: =(P31+Q31)/G31 -> -0.13088949 | Y31: =VLOOKUP(C31,每日行情!A:D,4,FALSE) -> 36.7 | Z31: =VLOOKUP(C31,每日行情!A:E,5,FALSE) -> 0.7 | AA31: =IF(I31="",((TODAY()-A31)*G31)/365.24,((I31-A31)*G31)/365.24) -> 1015.7705 | AB31: 台股
A32: 45925 | C32: 6548 | D32: =VLOOKUP(C32,每日行情!A:B,2,FALSE) -> 長科* | E32: 2000 | F32: 35.35 | G32: =E32*F32 -> 70700 | H32: 60 | I32: 45933 | J32: 36 | K32: =E32*J32 -> 72000 | L32: 61 | M32: 216 | N32: 0 | O32: =IF(I32="",E32*Y32,0) -> 0 | P32: =IF(I32="",R32-H32,(K32-H32-SUM(L32:N32)+R32-S32-T32)-G32)+(ROUND(R32*V32,0)-ROUND(R32*(1+V32),0)*W32) -> 963 | Q32: =IF(I32="",(O32-G32-(O32*0.1425%*0.65)-(O32*0.3%)-S32-T32),0) -> 0 | U32: =(V32*50%)/(1+50%*V32) -> 0 | W32: 0.11 | X32: =(P32+Q32)/G32 -> 0.013620934 | Y32: =VLOOKUP(C32,每日行情!A:D,4,FALSE) -> 83.4 | Z32: =VLOOKUP(C32,每日行情!A:E,5,FALSE) -> 1.2 | AA32: =IF(I32="",((TODAY()-A32)*G32)/365.24,((I32-A32)*G32)/365.24) -> 1548.5708 | AB32: 台股
A33: 45925 | C33: 2375 | D33: =VLOOKUP(C33,每日行情!A:B,2,FALSE) -> 凱美 | E33: 1000 | F33: 78.8 | G33: =E33*F33 -> 78800 | H33: 67 | I33: 45944 | J33: 76.8 | K33: =E33*J33 -> 76800 | L33: 65 | M33: 230 | N33: 0 | O33: =IF(I33="",E33*Y33,0) -> 0 | P33: =IF(I33="",R33-H33,(K33-H33-SUM(L33:N33)+R33-S33-T33)-G33)+(ROUND(R33*V33,0)-ROUND(R33*(1+V33),0)*W33) -> -2362 | Q33: =IF(I33="",(O33-G33-(O33*0.1425%*0.65)-(O33*0.3%)-S33-T33),0) -> 0 | U33: =(V33*50%)/(1+50%*V33) -> 0 | W33: 0.11 | X33: =(P33+Q33)/G33 -> -0.029974619 | Y33: =VLOOKUP(C33,每日行情!A:D,4,FALSE) -> 125.5 | Z33: =VLOOKUP(C33,每日行情!A:E,5,FALSE) -> -5.5 | AA33: =IF(I33="",((TODAY()-A33)*G33)/365.24,((I33-A33)*G33)/365.24) -> 4099.2224 | AB33: 台股
A34: 45925 | C34: 3628 | D34: =VLOOKUP(C34,每日行情!A:B,2,FALSE) -> 盈正 | E34: 1000 | F34: 59.1 | G34: =E34*F34 -> 59100 | H34: 50 | I34: 45939 | J34: 73.5 | K34: =E34*J34 -> 73500 | L34: 62 | M34: 220 | N34: 0 | O34: =IF(I34="",E34*Y34,0) -> 0 | P34: =IF(I34="",R34-H34,(K34-H34-SUM(L34:N34)+R34-S34-T34)-G34)+(ROUND(R34*V34,0)-ROUND(R34*(1+V34),0)*W34) -> 14068 | Q34: =IF(I34="",(O34-G34-(O34*0.1425%*0.65)-(O34*0.3%)-S34-T34),0) -> 0 | U34: =(V34*50%)/(1+50%*V34) -> 0 | W34: 0.11 | X34: =(P34+Q34)/G34 -> 0.23803723 | Y34: =VLOOKUP(C34,每日行情!A:D,4,FALSE) -> 71.5 | Z34: =VLOOKUP(C34,每日行情!A:E,5,FALSE) -> 1.4 | AA34: =IF(I34="",((TODAY()-A34)*G34)/365.24,((I34-A34)*G34)/365.24) -> 2265.3598 | AB34: 台股
A35: 45889 | C35: 3661 | D35: =VLOOKUP(C35,每日行情!A:B,2,FALSE) -> 世芯-KY | E35: 10 | F35: 3760 | G35: =E35*F35 -> 37600 | H35: 32 | I35: 45964 | J35: 3460 | K35: =E35*J35 -> 34600 | L35: 30 | M35: 104 | N35: 0 | O35: =IF(I35="",E35*Y35,0) -> 0 | P35: =IF(I35="",R35-H35,(K35-H35-SUM(L35:N35)+R35-S35-T35)-G35)+(ROUND(R35*V35,0)-ROUND(R35*(1+V35),0)*W35) -> -2852.04 | Q35: =IF(I35="",(O35-G35-(O35*0.1425%*0.65)-(O35*0.3%)-S35-T35),0) -> 0 | R35: 364 | S35: 10 | U35: =(V35*50%)/(1+50%*V35) -> 0 | W35: 0.11 | X35: =(P35+Q35)/G35 -> -0.075852128 | Y35: =VLOOKUP(C35,每日行情!A:D,4,FALSE) -> 3685 | Z35: =VLOOKUP(C35,每日行情!A:E,5,FALSE) -> -20 | AA35: =IF(I35="",((TODAY()-A35)*G35)/365.24,((I35-A35)*G35)/365.24) -> 7720.9506 | AB35: 台股
A36: 45924 | C36: 3661 | D36: =VLOOKUP(C36,每日行情!A:B,2,FALSE) -> 世芯-KY | E36: 10 | F36: 3420 | G36: =E36*F36 -> 34200 | H36: 29 | I36: 45964 | J36: 3460 | K36: =E36*J36 -> 34600 | L36: 30 | M36: 104 | N36: 0 | O36: =IF(I36="",E36*Y36,0) -> 0 | P36: =IF(I36="",R36-H36,(K36-H36-SUM(L36:N36)+R36-S36-T36)-G36)+(ROUND(R36*V36,0)-ROUND(R36*(1+V36),0)*W36) -> 237 | Q36: =IF(I36="",(O36-G36-(O36*0.1425%*0.65)-(O36*0.3%)-S36-T36),0) -> 0 | U36: =(V36*50%)/(1+50%*V36) -> 0 | W36: 0.11 | X36: =(P36+Q36)/G36 -> 0.0069298246 | Y36: =VLOOKUP(C36,每日行情!A:D,4,FALSE) -> 3685 | Z36: =VLOOKUP(C36,每日行情!A:E,5,FALSE) -> -20 | AA36: =IF(I36="",((TODAY()-A36)*G36)/365.24,((I36-A36)*G36)/365.24) -> 3745.4824 | AB36: 台股
A37: 45926 | C37: 3661 | D37: =VLOOKUP(C37,每日行情!A:B,2,FALSE) -> 世芯-KY | E37: 10 | F37: 3260 | G37: =E37*F37 -> 32600 | H37: 27 | I37: 45964 | J37: 3460 | K37: =E37*J37 -> 34600 | L37: 29 | M37: 104 | N37: 0 | O37: =IF(I37="",E37*Y37,0) -> 0 | P37: =IF(I37="",R37-H37,(K37-H37-SUM(L37:N37)+R37-S37-T37)-G37)+(ROUND(R37*V37,0)-ROUND(R37*(1+V37),0)*W37) -> 1840 | Q37: =IF(I37="",(O37-G37-(O37*0.1425%*0.65)-(O37*0.3%)-S37-T37),0) -> 0 | U37: =(V37*50%)/(1+50%*V37) -> 0 | W37: 0.11 | X37: =(P37+Q37)/G37 -> 0.056441718 | Y37: =VLOOKUP(C37,每日行情!A:D,4,FALSE) -> 3685 | Z37: =VLOOKUP(C37,每日行情!A:E,5,FALSE) -> -20 | AA37: =IF(I37="",((TODAY()-A37)*G37)/365.24,((I37-A37)*G37)/365.24) -> 3391.7424 | AB37: 台股
A38: 45944 | C38: 3661 | D38: =VLOOKUP(C38,每日行情!A:B,2,FALSE) -> 世芯-KY | E38: 10 | F38: 3170 | G38: =E38*F38 -> 31700 | H38: 27 | I38: 45964 | J38: 3460 | K38: =E38*J38 -> 34600 | L38: 29 | M38: 103 | N38: 0 | O38: =IF(I38="",E38*Y38,0) -> 0 | P38: =IF(I38="",R38-H38,(K38-H38-SUM(L38:N38)+R38-S38-T38)-G38)+(ROUND(R38*V38,0)-ROUND(R38*(1+V38),0)*W38) -> 2741 | Q38: =IF(I38="",(O38-G38-(O38*0.1425%*0.65)-(O38*0.3%)-S38-T38),0) -> 0 | U38: =(V38*50%)/(1+50%*V38) -> 0 | W38: 0.11 | X38: =(P38+Q38)/G38 -> 0.086466877 | Y38: =VLOOKUP(C38,每日行情!A:D,4,FALSE) -> 3685 | Z38: =VLOOKUP(C38,每日行情!A:E,5,FALSE) -> -20 | AA38: =IF(I38="",((TODAY()-A38)*G38)/365.24,((I38-A38)*G38)/365.24) -> 1735.8449 | AB38: 台股
A39: 46043 | C39: 50 | D39: =VLOOKUP(C39,每日行情!A:B,2,FALSE) -> 元大台灣50 | E39: 2000 | F39: 72.45 | G39: =E39*F39 -> 144900 | H39: 123 | I39: 46050 | J39: 74 | K39: =E39*J39 -> 148000 | L39: 126 | M39: 148 | N39: 0 | O39: =IF(I39="",E39*Y39,0) -> 0 | P39: =IF(I39="",R39-H39,(K39-H39-SUM(L39:N39)+R39-S39-T39)-G39)+(ROUND(R39*V39,0)-ROUND(R39*(1+V39),0)*W39) -> 4473 | Q39: =IF(I39="",(O39-G39-(O39*0.1425%*0.65)-(O39*0.3%)-S39-T39),0) -> 0 | R39: 2000 | S39: 10 | U39: =(V39*50%)/(1+50%*V39) -> 0 | W39: 0.11 | X39: =(P39+Q39)/G39 -> 0.030869565 | Y39: =VLOOKUP(C39,每日行情!A:D,4,FALSE) -> 109 | Z39: =VLOOKUP(C39,每日行情!A:E,5,FALSE) -> 0.1 | AA39: =IF(I39="",((TODAY()-A39)*G39)/365.24,((I39-A39)*G39)/365.24) -> 2777.0781 | AB39: 台股 ETF
A40: 45901 | C40: 56 | D40: =VLOOKUP(C40,每日行情!A:B,2,FALSE) -> 元大高股息 | E40: 285 | F40: 34.69 | G40: 9886 | H40: 1 | I40: 46051 | J40: 38.23 | K40: =E40*J40 -> 10895.55 | L40: 32 | M40: 38 | N40: 0 | O40: =IF(I40="",E40*Y40,0) -> 0 | P40: =IF(I40="",R40-H40,(K40-H40-SUM(L40:N40)+R40-S40-T40)-G40)+(ROUND(R40*V40,0)-ROUND(R40*(1+V40),0)*W40) -> 1223.14 | Q40: =IF(I40="",(O40-G40-(O40*0.1425%*0.65)-(O40*0.3%)-S40-T40),0) -> 0 | R40: 331 | S40: 10 | U40: =(V40*50%)/(1+50%*V40) -> 0 | W40: 0.11 | X40: =(P40+Q40)/G40 -> 0.12372446 | Y40: =VLOOKUP(C40,每日行情!A:D,4,FALSE) -> 58.75 | Z40: =VLOOKUP(C40,每日行情!A:E,5,FALSE) -> 0.5 | AA40: =IF(I40="",((TODAY()-A40)*G40)/365.24,((I40-A40)*G40)/365.24) -> 4060.0701 | AB40: 台股 ETF
...

Sheet YuHui-帳戶紀錄
A1: 日期 | B1: 台幣提出 | C1: 台幣存入 | D1: 台幣結餘 | E1: 美金提出 | F1: 美金存入 | G1: 美金結餘 | J1: 類別 | K1: 台幣本金 | L1: 美金本金
A2: 45698 | C2: 429 | D2: =C2-B2 -> 429 | G2: 0 | J2: 本金 | K2: =C2 -> 429 | L2: =G2 -> 0
A3: 45698 | C3: 50000 | D3: =D2+C3-B3 -> 50429 | G3: =G2+F3-E3 -> 0 | H3: 老木金援 | J3: 本金 | K3: =IF(J3="本金",C3-B3+K2,K2) -> 50429 | L3: =IF(J3="本金",F3+L2,L2) -> 0
A4: 45698 | C4: 500000 | D4: =D3+C4-B4 -> 550429 | G4: =G3+F4-E4 -> 0 | H4: 老木金援 | J4: 本金 | K4: =IF(J4="本金",C4-B4+K3,K3) -> 550429 | L4: =IF(J4="本金",F4+L3,L3) -> 0
A5: 45700 | B5: 113597 | D5: =D4+C5-B5 -> 436832 | G5: =G4+F5-E5 -> 0 | H5: 立端 | J5: 投資 | K5: =IF(J5="本金",C5-B5+K4,K4) -> 550429 | L5: =IF(J5="本金",F5+L4,L4) -> 0
A6: 45700 | B6: 118601 | D6: =D5+C6-B6 -> 318231 | G6: =G5+F6-E6 -> 0 | H6: 飛捷 | J6: 投資 | K6: =IF(J6="本金",C6-B6+K5,K5) -> 550429 | L6: =IF(J6="本金",F6+L5,L5) -> 0
A7: 45701 | B7: 92579 | D7: =D6+C7-B7 -> 225652 | G7: =G6+F7-E7 -> 0 | H7: 寬宏藝術 | J7: 投資 | K7: =IF(J7="本金",C7-B7+K6,K6) -> 550429 | L7: =IF(J7="本金",F7+L6,L6) -> 0
A8: 45705 | C8: 450000 | D8: =D7+C8-B8 -> 675652 | G8: =G7+F8-E8 -> 0 | H8: 老木金援 | J8: 本金 | K8: =IF(J8="本金",C8-B8+K7,K7) -> 1000429 | L8: =IF(J8="本金",F8+L7,L7) -> 0
A9: 45706 | B9: 29124 | D9: =D8+C9-B9 -> 646528 | G9: =G8+F9-E9 -> 0 | H9: 玉山金 | J9: 投資 | K9: =IF(J9="本金",C9-B9+K8,K8) -> 1000429 | L9: =IF(J9="本金",F9+L8,L8) -> 0
A10: 45706 | B10: 53345 | D10: =D9+C10-B10 -> 593183 | G10: =G9+F10-E10 -> 0 | H10: 華新 | J10: 投資 | K10: =IF(J10="本金",C10-B10+K9,K9) -> 1000429 | L10: =IF(J10="本金",F10+L9,L9) -> 0
A11: 45706 | B11: 69359 | D11: =D10+C11-B11 -> 523824 | G11: =G10+F11-E11 -> 0 | H11: 裕民 | J11: 投資 | K11: =IF(J11="本金",C11-B11+K10,K10) -> 1000429 | L11: =IF(J11="本金",F11+L10,L10) -> 0
A12: 45706 | B12: 110594 | D12: =D11+C12-B12 -> 413230 | G12: =G11+F12-E12 -> 0 | H12: 光寶科 | J12: 投資 | K12: =IF(J12="本金",C12-B12+K11,K11) -> 1000429 | L12: =IF(J12="本金",F12+L11,L11) -> 0
A13: 45708 | B13: 17920 | D13: =D12+C13-B13 -> 395310 | G13: =G12+F13-E13 -> 0 | H13: 凱基金 | J13: 投資 | K13: =IF(J13="本金",C13-B13+K12,K12) -> 1000429 | L13: =IF(J13="本金",F13+L12,L12) -> 0
A14: 45709 | B14: 87975 | D14: =D13+C14-B14 -> 307335 | G14: =G13+F14-E14 -> 0 | H14: 僑威 | J14: 投資 | K14: =IF(J14="本金",C14-B14+K13,K13) -> 1000429 | L14: =IF(J14="本金",F14+L13,L13) -> 0
A15: 45713 | C15: 84973 | D15: =D14+C15-B15 -> 392308 | G15: =G14+F15-E15 -> 0 | H15: 僑威 | J15: 投資 | K15: =IF(J15="本金",C15-B15+K14,K14) -> 1000429 | L15: =IF(J15="本金",F15+L14,L14) -> 0
A16: 45713 | B16: 70059 | D16: =D15+C16-B16 -> 322249 | G16: =G15+F16-E16 -> 0 | H16: 華碩 | J16: 投資 | K16: =IF(J16="本金",C16-B16+K15,K15) -> 1000429 | L16: =IF(J16="本金",F16+L15,L15) -> 0
A17: 45713 | C17: 500000 | D17: =D16+C17-B17 -> 822249 | G17: =G16+F17-E17 -> 0 | H17: 老木金援 | J17: 本金 | K17: =IF(J17="本金",C17-B17+K16,K16) -> 1500429 | L17: =IF(J17="本金",F17+L16,L16) -> 0
A18: 45715 | C18: 115056 | D18: =D17+C18-B18 -> 937305 | G18: =G17+F18-E18 -> 0 | H18: 立端 | J18: 投資 | K18: =IF(J18="本金",C18-B18+K17,K17) -> 1500429 | L18: =IF(J18="本金",F18+L17,L17) -> 0
A19: 45715 | C19: 500000 | D19: =D18+C19-B19 -> 1437305 | G19: =G18+F19-E19 -> 0 | H19: 老木金援 | J19: 本金 | K19: =IF(J19="本金",C19-B19+K18,K18) -> 2000429 | L19: =IF(J19="本金",F19+L18,L18) -> 0
A20: 45715 | B20: 654559 | D20: =D19+C20-B20 -> 782746 | G20: =G19+F20-E20 -> 0 | H20: 華城 | J20: 投資 | K20: =IF(J20="本金",C20-B20+K19,K19) -> 2000429 | L20: =IF(J20="本金",F20+L19,L19) -> 0
A21: 45715 | B21: 100 | D21: =D20+C21-B21 -> 782646 | G21: =G20+F21-E21 -> 0 | H21: 承銷申購 | J21: 投資 | K21: =IF(J21="本金",C21-B21+K20,K20) -> 2000429 | L21: =IF(J21="本金",F21+L20,L20) -> 0
A22: 45719 | C22: 91547 | D22: =D21+C22-B22 -> 874193 | G22: =G21+F22-E22 -> 0 | H22: 寬宏藝術 | J22: 投資 | K22: =IF(J22="本金",C22-B22+K21,K21) -> 2000429 | L22: =IF(J22="本金",F22+L21,L21) -> 0
A23: 45719 | B23: 564482 | D23: =D22+C23-B23 -> 309711 | G23: =G22+F23-E23 -> 0 | H23: 群聯 | J23: 投資 | K23: =IF(J23="本金",C23-B23+K22,K22) -> 2000429 | L23: =IF(J23="本金",F23+L22,L22) -> 0
A24: 45720 | C24: 18076 | D24: =D23+C24-B24 -> 327787 | G24: =G23+F24-E24 -> 0 | H24: 凱基金 | J24: 投資 | K24: =IF(J24="本金",C24-B24+K23,K23) -> 2000429 | L24: =IF(J24="本金",F24+L23,L23) -> 0
A25: 45720 | C25: 29387 | D25: =D24+C25-B25 -> 357174 | G25: =G24+F25-E25 -> 0 | H25: 玉山金 | J25: 投資 | K25: =IF(J25="本金",C25-B25+K24,K24) -> 2000429 | L25: =IF(J25="本金",F25+L24,L24) -> 0
A26: 45720 | C26: 109576 | D26: =D25+C26-B26 -> 466750 | G26: =G25+F26-E26 -> 0 | H26: 光寶科 | J26: 投資 | K26: =IF(J26="本金",C26-B26+K25,K25) -> 2000429 | L26: =IF(J26="本金",F26+L25,L25) -> 0
A27: 45720 | C27: 161875 | D27: =D26+C27-B27 -> 628625 | G27: =G26+F27-E27 -> 0 | H27: 飛捷 | J27: 投資 | K27: =IF(J27="本金",C27-B27+K26,K26) -> 2000429 | L27: =IF(J27="本金",F27+L26,L26) -> 0
A28: 45722 | C28: 55139 | D28: =D27+C28-B28 -> 683764 | G28: =G27+F28-E28 -> 0 | H28: 華新 | J28: 投資 | K28: =IF(J28="本金",C28-B28+K27,K27) -> 2000429 | L28: =IF(J28="本金",F28+L27,L27) -> 0 | N28: 683764 | O28: =D28-N28 -> 0
A29: 45723 | B29: 172147 | D29: =D28+C29-B29 -> 511617 | G29: =G28+F29-E29 -> 0 | H29: 帆宣 | J29: 投資 | K29: =IF(J29="本金",C29-B29+K28,K28) -> 2000429 | L29: =IF(J29="本金",F29+L28,L28) -> 0
A30: 45726 | B30: 81769 | D30: =D29+C30-B30 -> 429848 | G30: =G29+F30-E30 -> 0 | H30: 矽格 | J30: 投資 | K30: =IF(J30="本金",C30-B30+K29,K29) -> 2000429 | L30: =IF(J30="本金",F30+L29,L29) -> 0
A31: 45726 | B31: 49242 | D31: =D30+C31-B31 -> 380606 | G31: =G30+F31-E31 -> 0 | H31: 大成鋼 | J31: 投資 | K31: =IF(J31="本金",C31-B31+K30,K30) -> 2000429 | L31: =IF(J31="本金",F31+L30,L30) -> 0
A32: 45729 | C32: 64352 | D32: =D31+C32-B32 -> 444958 | G32: =G31+F32-E32 -> 0 | H32: 華碩 | J32: 投資 | K32: =IF(J32="本金",C32-B32+K31,K31) -> 2000429 | L32: =IF(J32="本金",F32+L31,L31) -> 0
A33: 45729 | C33: 75210 | D33: =D32+C33-B33 -> 520168 | G33: =G32+F33-E33 -> 0 | H33: 矽格 | J33: 投資 | K33: =IF(J33="本金",C33-B33+K32,K32) -> 2000429 | L33: =IF(J33="本金",F33+L32,L32) -> 0
A34: 45729 | C34: 587726 | D34: =D33+C34-B34 -> 1107894 | G34: =G33+F34-E34 -> 0 | H34: 華城 | J34: 投資 | K34: =IF(J34="本金",C34-B34+K33,K33) -> 2000429 | L34: =IF(J34="本金",F34+L33,L33) -> 0
A35: 45730 | C35: 48663 | D35: =D34+C35-B35 -> 1156557 | G35: =G34+F35-E35 -> 0 | H35: 大成鋼 | J35: 投資 | K35: =IF(J35="本金",C35-B35+K34,K34) -> 2000429 | L35: =IF(J35="本金",F35+L34,L34) -> 0
A36: 45730 | C36: 70329 | D36: =D35+C36-B36 -> 1226886 | G36: =G35+F36-E36 -> 0 | H36: 裕民 | J36: 投資 | K36: =IF(J36="本金",C36-B36+K35,K35) -> 2000429 | L36: =IF(J36="本金",F36+L35,L35) -> 0
A37: 45730 | B37: 86874 | D37: =D36+C37-B37 -> 1140012 | G37: =G36+F37-E37 -> 0 | H37: 新盛力 | J37: 投資 | K37: =IF(J37="本金",C37-B37+K36,K36) -> 2000429 | L37: =IF(J37="本金",F37+L36,L36) -> 0
A38: 45733 | C38: 2319 | D38: =D37+C38-B38 -> 1142331 | G38: =G37+F38-E38 -> 0 | H38: 順達 | J38: 投資 | K38: =IF(J38="本金",C38-B38+K37,K37) -> 2000429 | L38: =IF(J38="本金",F38+L37,L37) -> 0
A39: 45733 | C39: 161376 | D39: =D38+C39-B39 -> 1303707 | G39: =G38+F39-E39 -> 0 | H39: 帆宣 | J39: 投資 | K39: =IF(J39="本金",C39-B39+K38,K38) -> 2000429 | L39: =IF(J39="本金",F39+L38,L38) -> 0
A40: 45734 | C40: 2449 | D40: =D39+C40-B40 -> 1306156 | G40: =G39+F40-E40 -> 0 | H40: 波若威 | J40: 投資 | K40: =IF(J40="本金",C40-B40+K39,K39) -> 2000429 | L40: =IF(J40="本金",F40+L39,L39) -> 0 | N40: 1306016 | O40: =D40-N40 -> 140
...

Sheet 2025
A1: 買進日期 | B1: 種類 | C1: 股票代號 | D1: 股票名稱 | E1: 股數 | F1: 買進價 | G1: 成交金額 | H1: 手續費 | I1: 賣出日期 | J1: 賣出價 | K1: 成交金額 | L1: 手續費 | M1: 交易稅 | N1: 證所稅 | O1: 參考現值 | P1: 已實現損益 | Q1: 未實現損益 | R1: 除息 | S1: 手續費 | T1: 健保補充保費 | U1: 實質扣抵稅率 | V1: 扣抵稅率 | W1: 所得稅率 | X1: 投資報酬率 | Y1: 今日股價 | Z1: 漲跌 | AB1: 買進理由 | AC1: 賣出理由
A2: 45707 | C2: 3078 | D2: 僑威 | E2: 1000 | F2: 87.9 | G2: =E2*F2 -> 87900 | H2: 75 | I2: 45709 | J2: 85.3 | K2: =E2*J2 -> 85300 | L2: 72 | M2: 255 | N2: 0 | O2: =IF(I2="",E2*Y2,0) -> 0 | P2: =IF(I2="",R2-H2,(K2-H2-SUM(L2:N2)+R2-S2-T2)-G2)+(ROUND(R2*V2,0)-ROUND(R2*(1+V2),0)*W2) -> -3012 | Q2: =IF(I2="",(O2-G2-(O2*0.1425%*0.65)-(O2*0.3%)-S2-T2),0) -> 0 | S2: 10 | U2: =(V2*50%)/(1+50%*V2) -> 0 | W2: 0.11 | X2: =(P2+Q2)/G2 -> -0.034266212 | Y2: =VLOOKUP(C2,每日行情!A:D,4,FALSE) -> 47.3 | Z2: =VLOOKUP(C2,每日行情!A:E,5,FALSE) -> -0.1 | AA2: =IF(I2="",((TODAY()-A2)*G2)/365.24,((I2-A2)*G2)/365.24) -> 481.32735 | AB2: 強勢股 | AC2: 破10日線，認賠出場
A3: 45698 | C3: 6245 | D3: 立端 | E3: 1000 | F3: 113.5 | G3: =E3*F3 -> 113500 | H3: 97 | I3: 45713 | J3: 115.5 | K3: =E3*J3 -> 115500 | L3: 98 | M3: 346 | N3: 0 | O3: =IF(I3="",E3*Y3,0) -> 0 | P3: =IF(I3="",R3-H3,(K3-H3-SUM(L3:N3)+R3-S3-T3)-G3)+(ROUND(R3*V3,0)-ROUND(R3*(1+V3),0)*W3) -> 1449 | Q3: =IF(I3="",(O3-G3-(O3*0.1425%*0.65)-(O3*0.3%)-S3-T3),0) -> 0 | S3: 10 | U3: =(V3*50%)/(1+50%*V3) -> 0 | W3: 0.11 | X3: =(P3+Q3)/G3 -> 0.01276652 | Y3: =VLOOKUP(C3,每日行情!A:D,4,FALSE) -> 89.3 | Z3: =VLOOKUP(C3,每日行情!A:E,5,FALSE) -> 1.6 | AA3: =IF(I3="",((TODAY()-A3)*G3)/365.24,((I3-A3)*G3)/365.24) -> 4661.3186 | AB3: 強勢股 | AC3: 破5日線，獲利了結
A4: 45699 | C4: 6596 | D4: 寬宏藝術 | E4: 1000 | F4: 92.5 | G4: =E4*F4 -> 92500 | H4: 79 | I4: 45714 | J4: 91.9 | K4: =E4*J4 -> 91900 | L4: 78 | M4: 275 | N4: 0 | O4: =IF(I4="",E4*Y4,0) -> 0 | P4: =IF(I4="",R4-H4,(K4-H4-SUM(L4:N4)+R4-S4-T4)-G4)+(ROUND(R4*V4,0)-ROUND(R4*(1+V4),0)*W4) -> -1042 | Q4: =IF(I4="",(O4-G4-(O4*0.1425%*0.65)-(O4*0.3%)-S4-T4),0) -> 0 | S4: 10 | U4: =(V4*50%)/(1+50%*V4) -> 0 | W4: 0.11 | X4: =(P4+Q4)/G4 -> -0.011264865 | Y4: =VLOOKUP(C4,每日行情!A:D,4,FALSE) -> 96.1 | Z4: =VLOOKUP(C4,每日行情!A:E,5,FALSE) -> 0.8 | AA4: =IF(I4="",((TODAY()-A4)*G4)/365.24,((I4-A4)*G4)/365.24) -> 3798.872 | AB4: 強勢股 | AC4: 破10日線，認賠出場
A5: 45702 | C5: 2301 | D5: 光寶科 | E5: 1000 | F5: 110.5 | G5: =E5*F5 -> 110500 | H5: 94 | I5: 45715 | J5: 110 | K5: =E5*J5 -> 110000 | L5: 94 | M5: 330 | N5: 0 | O5: =IF(I5="",E5*Y5,0) -> 0 | P5: =IF(I5="",R5-H5,(K5-H5-SUM(L5:N5)+R5-S5-T5)-G5)+(ROUND(R5*V5,0)-ROUND(R5*(1+V5),0)*W5) -> -1028 | Q5: =IF(I5="",(O5-G5-(O5*0.1425%*0.65)-(O5*0.3%)-S5-T5),0) -> 0 | S5: 10 | U5: =(V5*50%)/(1+50%*V5) -> 0 | W5: 0.11 | X5: =(P5+Q5)/G5 -> -0.0093031674 | Y5: =VLOOKUP(C5,每日行情!A:D,4,FALSE) -> 264.5 | Z5: =VLOOKUP(C5,每日行情!A:E,5,FALSE) -> -3.5 | AA5: =IF(I5="",((TODAY()-A5)*G5)/365.24,((I5-A5)*G5)/365.24) -> 3933.0303 | AB5: 強勢股 | AC5: 破10日線，認賠出場
A6: 45706 | C6: 2883 | D6: 凱基金 | E6: 1000 | F6: 17.9 | G6: =E6*F6 -> 17900 | H6: 20 | I6: 45715 | J6: 18.15 | K6: =E6*J6 -> 18150 | L6: 20 | M6: 54 | N6: 0 | O6: =IF(I6="",E6*Y6,0) -> 0 | P6: =IF(I6="",R6-H6,(K6-H6-SUM(L6:N6)+R6-S6-T6)-G6)+(ROUND(R6*V6,0)-ROUND(R6*(1+V6),0)*W6) -> 146 | Q6: =IF(I6="",(O6-G6-(O6*0.1425%*0.65)-(O6*0.3%)-S6-T6),0) -> 0 | S6: 10 | U6: =(V6*50%)/(1+50%*V6) -> 0 | W6: 0.11 | X6: =(P6+Q6)/G6 -> 0.0081564246 | Y6: =VLOOKUP(C6,每日行情!A:D,4,FALSE) -> 39.1 | Z6: =VLOOKUP(C6,每日行情!A:E,5,FALSE) -> 0.7 | AA6: =IF(I6="",((TODAY()-A6)*G6)/365.24,((I6-A6)*G6)/365.24) -> 441.07984 | AB6: 強勢股 | AC6: 破10日線，獲利了結
A7: 45702 | C7: 2884 | D7: 玉山金 | E7: 1000 | F7: 29.1 | G7: =E7*F7 -> 29100 | H7: 24 | I7: 45715 | J7: 29.5 | K7: =E7*J7 -> 29500 | L7: 25 | M7: 88 | N7: 0 | O7: =IF(I7="",E7*Y7,0) -> 0 | P7: =IF(I7="",R7-H7,(K7-H7-SUM(L7:N7)+R7-S7-T7)-G7)+(ROUND(R7*V7,0)-ROUND(R7*(1+V7),0)*W7) -> 253 | Q7: =IF(I7="",(O7-G7-(O7*0.1425%*0.65)-(O7*0.3%)-S7-T7),0) -> 0 | S7: 10 | U7: =(V7*50%)/(1+50%*V7) -> 0 | W7: 0.11 | X7: =(P7+Q7)/G7 -> 0.0086941581 | Y7: =VLOOKUP(C7,每日行情!A:D,4,FALSE) -> 49.15 | Z7: =VLOOKUP(C7,每日行情!A:E,5,FALSE) -> 0.35 | AA7: =IF(I7="",((TODAY()-A7)*G7)/365.24,((I7-A7)*G7)/365.24) -> 1035.7573 | AB7: 強勢股 | AC7: 破10日線，獲利了結
A8: 45698 | C8: 6206 | D8: 飛捷 | E8: 1000 | F8: 118.5 | G8: =E8*F8 -> 118500 | H8: 101 | I8: 45715 | J8: 162.5 | K8: =E8*J8 -> 162500 | L8: 138 | M8: 487 | N8: 0 | O8: =IF(I8="",E8*Y8,0) -> 0 | P8: =IF(I8="",R8-H8,(K8-H8-SUM(L8:N8)+R8-S8-T8)-G8)+(ROUND(R8*V8,0)-ROUND(R8*(1+V8),0)*W8) -> 43264 | Q8: =IF(I8="",(O8-G8-(O8*0.1425%*0.65)-(O8*0.3%)-S8-T8),0) -> 0 | S8: 10 | U8: =(V8*50%)/(1+50%*V8) -> 0 | W8: 0.11 | X8: =(P8+Q8)/G8 -> 0.36509705 | Y8: =VLOOKUP(C8,每日行情!A:D,4,FALSE) -> 36.56 | Z8: =VLOOKUP(C8,每日行情!A:E,5,FALSE) -> 0.4 | AA8: =IF(I8="",((TODAY()-A8)*G8)/365.24,((I8-A8)*G8)/365.24) -> 5515.5514 | AB8: 強勢股 | AC8: 破10日線，獲利了結
A9: 45702 | C9: 1605 | D9: 華新 | E9: 1000 | F9: 26.65 | G9: =E9*F9 -> 26650 | H9: 23 | I9: 45720 | J9: 27.6 | K9: =E9*J9 -> 27600 | L9: 23 | M9: 82 | N9: 0 | O9: =IF(I9="",E9*Y9,0) -> 0 | P9: =IF(I9="",R9-H9,(K9-H9-SUM(L9:N9)+R9-S9-T9)-G9)+(ROUND(R9*V9,0)-ROUND(R9*(1+V9),0)*W9) -> 812 | Q9: =IF(I9="",(O9-G9-(O9*0.1425%*0.65)-(O9*0.3%)-S9-T9),0) -> 0 | S9: 10 | U9: =(V9*50%)/(1+50%*V9) -> 0 | W9: 0.11 | X9: =(P9+Q9)/G9 -> 0.030469043 | Y9: =VLOOKUP(C9,每日行情!A:D,4,FALSE) -> 38.5 | Z9: =VLOOKUP(C9,每日行情!A:E,5,FALSE) -> 0.8 | AA9: =IF(I9="",((TODAY()-A9)*G9)/365.24,((I9-A9)*G9)/365.24) -> 1313.383 | AB9: 強勢股 | AC9: 破10日線，獲利了結
A10: 45702 | C10: 1605 | D10: 華新 | E10: 1000 | F10: 26.65 | G10: =E10*F10 -> 26650 | H10: 22 | I10: 45721 | J10: 27.75 | K10: =E10*J10 -> 27750 | L10: 23 | M10: 83 | N10: 0 | O10: =IF(I10="",E10*Y10,0) -> 0 | P10: =IF(I10="",R10-H10,(K10-H10-SUM(L10:N10)+R10-S10-T10)-G10)+(ROUND(R10*V10,0)-ROUND(R10*(1+V10),0)*W10) -> 962 | Q10: =IF(I10="",(O10-G10-(O10*0.1425%*0.65)-(O10*0.3%)-S10-T10),0) -> 0 | S10: 10 | U10: =(V10*50%)/(1+50%*V10) -> 0 | W10: 0.11 | X10: =(P10+Q10)/G10 -> 0.036097561 | Y10: =VLOOKUP(C10,每日行情!A:D,4,FALSE) -> 38.5 | Z10: =VLOOKUP(C10,每日行情!A:E,5,FALSE) -> 0.8 | AA10: =IF(I10="",((TODAY()-A10)*G10)/365.24,((I10-A10)*G10)/365.24) -> 1386.3487 | AB10: 強勢股 | AC10: 破10日線，獲利了結
A11: 45709 | C11: 2357 | D11: 華碩 | E11: 100 | F11: 700 | G11: =E11*F11 -> 70000 | H11: 59 | I11: 45727 | J11: 646 | K11: =E11*J11 -> 64600 | L11: 55 | M11: 193 | N11: 0 | O11: =IF(I11="",E11*Y11,0) -> 0 | P11: =IF(I11="",R11-H11,(K11-H11-SUM(L11:N11)+R11-S11-T11)-G11)+(ROUND(R11*V11,0)-ROUND(R11*(1+V11),0)*W11) -> -5717 | Q11: =IF(I11="",(O11-G11-(O11*0.1425%*0.65)-(O11*0.3%)-S11-T11),0) -> 0 | S11: 10 | U11: =(V11*50%)/(1+50%*V11) -> 0 | W11: 0.11 | X11: =(P11+Q11)/G11 -> -0.081671429 | Y11: =VLOOKUP(C11,每日行情!A:D,4,FALSE) -> 994 | Z11: =VLOOKUP(C11,每日行情!A:E,5,FALSE) -> 19 | AA11: =IF(I11="",((TODAY()-A11)*G11)/365.24,((I11-A11)*G11)/365.24) -> 3449.7864 | AB11: 強勢股 | AC11: 破10日線，認賠出場
A12: 45713 | C12: 1519 | D12: 華城 | E12: 1000 | F12: 654 | G12: =E12*F12 -> 654000 | H12: 559 | I12: 45727 | J12: 590 | K12: =E12*J12 -> 590000 | L12: 504 | M12: 1770 | N12: 0 | O12: =IF(I12="",E12*Y12,0) -> 0 | P12: =IF(I12="",R12-H12,(K12-H12-SUM(L12:N12)+R12-S12-T12)-G12)+(ROUND(R12*V12,0)-ROUND(R12*(1+V12),0)*W12) -> -66843 | Q12: =IF(I12="",(O12-G12-(O12*0.1425%*0.65)-(O12*0.3%)-S12-T12),0) -> 0 | S12: 10 | U12: =(V12*50%)/(1+50%*V12) -> 0 | W12: 0.11 | X12: =(P12+Q12)/G12 -> -0.10220642 | Y12: =VLOOKUP(C12,每日行情!A:D,4,FALSE) -> 656 | Z12: =VLOOKUP(C12,每日行情!A:E,5,FALSE) -> 7 | AA12: =IF(I12="",((TODAY()-A12)*G12)/365.24,((I12-A12)*G12)/365.24) -> 25068.448 | AB12: 強勢股 | AC12: 破10日線，認賠出場
A13: 45723 | C13: 6257 | D13: 矽格 | E13: 1000 | F13: 81.7 | G13: =E13*F13 -> 81700 | H13: 69 | I13: 45727 | J13: 75.5 | K13: =E13*J13 -> 75500 | L13: 64 | M13: 226 | N13: 0 | O13: =IF(I13="",E13*Y13,0) -> 0 | P13: =IF(I13="",R13-H13,(K13-H13-SUM(L13:N13)+R13-S13-T13)-G13)+(ROUND(R13*V13,0)-ROUND(R13*(1+V13),0)*W13) -> -6569 | Q13: =IF(I13="",(O13-G13-(O13*0.1425%*0.65)-(O13*0.3%)-S13-T13),0) -> 0 | S13: 10 | U13: =(V13*50%)/(1+50%*V13) -> 0 | W13: 0.11 | X13: =(P13+Q13)/G13 -> -0.080403917 | Y13: =VLOOKUP(C13,每日行情!A:D,4,FALSE) -> 252 | Z13: =VLOOKUP(C13,每日行情!A:E,5,FALSE) -> -6 | AA13: =IF(I13="",((TODAY()-A13)*G13)/365.24,((I13-A13)*G13)/365.24) -> 894.75413 | AB13: 強勢股 | AC13: 破10日線，認賠出場
A14: 45723 | C14: 2027 | D14: =VLOOKUP(C14,每日行情!A:B,2,FALSE) -> 大成鋼 | E14: 1000 | F14: 49.2 | G14: =E14*F14 -> 49200 | H14: 42 | I14: 45728 | J14: 48.85 | K14: =E14*J14 -> 48850 | L14: 41 | M14: 146 | N14: 0 | O14: =IF(I14="",E14*Y14,0) -> 0 | P14: =IF(I14="",R14-H14,(K14-H14-SUM(L14:N14)+R14-S14-T14)-G14)+(ROUND(R14*V14,0)-ROUND(R14*(1+V14),0)*W14) -> -589 | Q14: =IF(I14="",(O14-G14-(O14*0.1425%*0.65)-(O14*0.3%)-S14-T14),0) -> 0 | S14: 10 | U14: =(V14*50%)/(1+50%*V14) -> 0 | W14: 0.11 | X14: =(P14+Q14)/G14 -> -0.011971545 | Y14: =VLOOKUP(C14,每日行情!A:D,4,FALSE) -> 50.9 | Z14: =VLOOKUP(C14,每日行情!A:E,5,FALSE) -> 1.6 | AA14: =IF(I14="",((TODAY()-A14)*G14)/365.24,((I14-A14)*G14)/365.24) -> 673.52973 | AB14: 強勢股 | AC14: 破10日線，認賠出場
A15: 45702 | C15: 2606 | D15: =VLOOKUP(C15,每日行情!A:B,2,FALSE) -> 裕民 | E15: 1000 | F15: 69.3 | G15: =E15*F15 -> 69300 | H15: 59 | I15: 45728 | J15: 70.6 | K15: =E15*J15 -> 70600 | L15: 60 | M15: 211 | N15: 0 | O15: =IF(I15="",E15*Y15,0) -> 0 | P15: =IF(I15="",R15-H15,(K15-H15-SUM(L15:N15)+R15-S15-T15)-G15)+(ROUND(R15*V15,0)-ROUND(R15*(1+V15),0)*W15) -> 960 | Q15: =IF(I15="",(O15-G15-(O15*0.1425%*0.65)-(O15*0.3%)-S15-T15),0) -> 0 | S15: 10 | U15: =(V15*50%)/(1+50%*V15) -> 0 | W15: 0.11 | X15: =(P15+Q15)/G15 -> 0.013852814 | Y15: =VLOOKUP(C15,每日行情!A:D,4,FALSE) -> 75.2 | Z15: =VLOOKUP(C15,每日行情!A:E,5,FALSE) -> -0.8 | AA15: =IF(I15="",((TODAY()-A15)*G15)/365.24,((I15-A15)*G15)/365.24) -> 4933.1946 | AB15: 強勢股 | AC15: 破10日線，獲利了結
A16: 45729 | C16: 3211 | D16: =VLOOKUP(C16,每日行情!A:B,2,FALSE) -> 順達 | E16: 1000 | F16: 210.5 | G16: =E16*F16 -> 210500 | H16: 179 | I16: 45729 | J16: 213.5 | K16: =E16*J16 -> 213500 | L16: 182 | M16: 320 | N16: 0 | O16: =IF(I16="",E16*Y16,0) -> 0 | P16: =IF(I16="",R16-H16,(K16-H16-SUM(L16:N16)+R16-S16-T16)-G16)+(ROUND(R16*V16,0)-ROUND(R16*(1+V16),0)*W16) -> 2309 | Q16: =IF(I16="",(O16-G16-(O16*0.1425%*0.65)-(O16*0.3%)-S16-T16),0) -> 0 | S16: 10 | U16: =(V16*50%)/(1+50%*V16) -> 0 | W16: 0.11 | X16: =(P16+Q16)/G16 -> 0.010969121 | Y16: =VLOOKUP(C16,每日行情!A:D,4,FALSE) -> 346 | Z16: =VLOOKUP(C16,每日行情!A:E,5,FALSE) -> -3 | AA16: =IF(I16="",((TODAY()-A16)*G16)/365.24,((I16-A16)*G16)/365.24) -> 0 | AB16: 強勢股 | AC16: 當沖
A17: 45721 | C17: 6196 | D17: =VLOOKUP(C17,每日行情!A:B,2,FALSE) -> 帆宣 | E17: 1000 | F17: 172 | G17: =E17*F17 -> 172000 | H17: 147 | I17: 45729 | J17: 162 | K17: =E17*J17 -> 162000 | L17: 138 | M17: 486 | N17: 0 | O17: =IF(I17="",E17*Y17,0) -> 0 | P17: =IF(I17="",R17-H17,(K17-H17-SUM(L17:N17)+R17-S17-T17)-G17)+(ROUND(R17*V17,0)-ROUND(R17*(1+V17),0)*W17) -> -10781 | Q17: =IF(I17="",(O17-G17-(O17*0.1425%*0.65)-(O17*0.3%)-S17-T17),0) -> 0 | S17: 10 | U17: =(V17*50%)/(1+50%*V17) -> 0 | W17: 0.11 | X17: =(P17+Q17)/G17 -> -0.062680233 | Y17: =VLOOKUP(C17,每日行情!A:D,4,FALSE) -> 609 | Z17: =VLOOKUP(C17,每日行情!A:E,5,FALSE) -> -4 | AA17: =IF(I17="",((TODAY()-A17)*G17)/365.24,((I17-A17)*G17)/365.24) -> 3767.3858 | AB17: 強勢股 | AC17: 破10日線，認賠出場
A18: 45728 | C18: 4931 | D18: =VLOOKUP(C18,每日行情!A:B,2,FALSE) -> 新盛力 | E18: 1000 | F18: 86.8 | G18: =E18*F18 -> 86800 | H18: 74 | I18: 45730 | J18: 87.6 | K18: =E18*J18 -> 87600 | L18: 74 | M18: 262 | N18: 0 | O18: =IF(I18="",E18*Y18,0) -> 0 | P18: =IF(I18="",R18-H18,(K18-H18-SUM(L18:N18)+R18-S18-T18)-G18)+(ROUND(R18*V18,0)-ROUND(R18*(1+V18),0)*W18) -> 380 | Q18: =IF(I18="",(O18-G18-(O18*0.1425%*0.65)-(O18*0.3%)-S18-T18),0) -> 0 | S18: 10 | U18: =(V18*50%)/(1+50%*V18) -> 0 | W18: 0.11 | X18: =(P18+Q18)/G18 -> 0.0043778802 | Y18: =VLOOKUP(C18,每日行情!A:D,4,FALSE) -> 217 | Z18: =VLOOKUP(C18,每日行情!A:E,5,FALSE) -> 4 | AA18: =IF(I18="",((TODAY()-A18)*G18)/365.24,((I18-A18)*G18)/365.24) -> 475.30391 | AB18: 強勢股 | AC18: 大盤籌碼軍空頭，股價下跌即賣出，收盤時未破5日線
A19: 45730 | C19: 3163 | D19: =VLOOKUP(C19,每日行情!A:B,2,FALSE) -> 波若威 | E19: 1000 | F19: 170 | G19: =E19*F19 -> 170000 | H19: 145 | I19: 45730 | J19: 173 | K19: =E19*J19 -> 173000 | L19: 147 | M19: 259 | N19: 0 | O19: =IF(I19="",E19*Y19,0) -> 0 | P19: =IF(I19="",R19-H19,(K19-H19-SUM(L19:N19)+R19-S19-T19)-G19)+(ROUND(R19*V19,0)-ROUND(R19*(1+V19),0)*W19) -> 2439 | Q19: =IF(I19="",(O19-G19-(O19*0.1425%*0.65)-(O19*0.3%)-S19-T19),0) -> 0 | S19: 10 | U19: =(V19*50%)/(1+50%*V19) -> 0 | W19: 0.11 | X19: =(P19+Q19)/G19 -> 0.014347059 | Y19: =VLOOKUP(C19,每日行情!A:D,4,FALSE) -> 589 | Z19: =VLOOKUP(C19,每日行情!A:E,5,FALSE) -> -15 | AA19: =IF(I19="",((TODAY()-A19)*G19)/365.24,((I19-A19)*G19)/365.24) -> 0 | AB19: 強勢股 | AC19: 當沖
A20: 45736 | C20: 2634 | D20: =VLOOKUP(C20,每日行情!A:B,2,FALSE) -> 漢翔 | E20: 1000 | F20: 52.9 | G20: =E20*F20 -> 52900 | H20: 45 | I20: 45736 | J20: 51.1 | K20: =E20*J20 -> 51100 | L20: 43 | M20: 76 | N20: 0 | O20: =IF(I20="",E20*Y20,0) -> 0 | P20: =IF(I20="",R20-H20,(K20-H20-SUM(L20:N20)+R20-S20-T20)-G20)+(ROUND(R20*V20,0)-ROUND(R20*(1+V20),0)*W20) -> -1974 | Q20: =IF(I20="",(O20-G20-(O20*0.1425%*0.65)-(O20*0.3%)-S20-T20),0) -> 0 | S20: 10 | U20: =(V20*50%)/(1+50%*V20) -> 0 | W20: 0.11 | X20: =(P20+Q20)/G20 -> -0.03731569 | Y20: =VLOOKUP(C20,每日行情!A:D,4,FALSE) -> 62.1 | Z20: =VLOOKUP(C20,每日行情!A:E,5,FALSE) -> 1.4 | AA20: =IF(I20="",((TODAY()-A20)*G20)/365.24,((I20-A20)*G20)/365.24) -> 0 | AB20: 強勢股 | AC20: 當沖
A21: 45714 | C21: 8299 | D21: =VLOOKUP(C21,每日行情!A:B,2,FALSE) -> 群聯 | E21: 1000 | F21: 564 | G21: =E21*F21 -> 564000 | H21: 482 | I21: 45741 | J21: 573 | K21: =E21*J21 -> 573000 | L21: 489 | M21: 1719 | N21: 0 | O21: =IF(I21="",E21*Y21,0) -> 0 | P21: =IF(I21="",R21-H21,(K21-H21-SUM(L21:N21)+R21-S21-T21)-G21)+(ROUND(R21*V21,0)-ROUND(R21*(1+V21),0)*W21) -> 6300 | Q21: =IF(I21="",(O21-G21-(O21*0.1425%*0.65)-(O21*0.3%)-S21-T21),0) -> 0 | S21: 10 | U21: =(V21*50%)/(1+50%*V21) -> 0 | W21: 0.11 | X21: =(P21+Q21)/G21 -> 0.011170213 | Y21: =VLOOKUP(C21,每日行情!A:D,4,FALSE) -> 1890 | Z21: =VLOOKUP(C21,每日行情!A:E,5,FALSE) -> 60 | AA21: =IF(I21="",((TODAY()-A21)*G21)/365.24,((I21-A21)*G21)/365.24) -> 41693.133 | AB21: 強勢股 | AC21: 破20MA，獲利了結
A22: 45737 | C22: 1319 | D22: =VLOOKUP(C22,每日行情!A:B,2,FALSE) -> 東陽 | E22: 1000 | F22: 138 | G22: =E22*F22 -> 138000 | H22: 117 | I22: 45742 | J22: 133 | K22: =E22*J22 -> 133000 | L22: 113 | M22: 399 | N22: 0 | O22: =IF(I22="",E22*Y22,0) -> 0 | P22: =IF(I22="",R22-H22,(K22-H22-SUM(L22:N22)+R22-S22-T22)-G22)+(ROUND(R22*V22,0)-ROUND(R22*(1+V22),0)*W22) -> -5639 | Q22: =IF(I22="",(O22-G22-(O22*0.1425%*0.65)-(O22*0.3%)-S22-T22),0) -> 0 | S22: 10 | U22: =(V22*50%)/(1+50%*V22) -> 0 | W22: 0.11 | X22: =(P22+Q22)/G22 -> -0.040862319 | Y22: =VLOOKUP(C22,每日行情!A:D,4,FALSE) -> 83.5 | Z22: =VLOOKUP(C22,每日行情!A:E,5,FALSE) -> 0.2 | AA22: =IF(I22="",((TODAY()-A22)*G22)/365.24,((I22-A22)*G22)/365.24) -> 1889.1688 | AB22: 強勢股 | AC22: 破10日線，認賠出場
A23: 45735 | C23: 2609 | D23: =VLOOKUP(C23,每日行情!A:B,2,FALSE) -> 陽明 | E23: 1000 | F23: 77.2 | G23: =E23*F23 -> 77200 | H23: 45 | I23: 45743 | J23: 76.2 | K23: =E23*J23 -> 76200 | L23: 65 | M23: 228 | N23: 0 | O23: =IF(I23="",E23*Y23,0) -> 0 | P23: =IF(I23="",R23-H23,(K23-H23-SUM(L23:N23)+R23-S23-T23)-G23)+(ROUND(R23*V23,0)-ROUND(R23*(1+V23),0)*W23) -> -1348 | Q23: =IF(I23="",(O23-G23-(O23*0.1425%*0.65)-(O23*0.3%)-S23-T23),0) -> 0 | S23: 10 | U23: =(V23*50%)/(1+50%*V23) -> 0 | W23: 0.11 | X23: =(P23+Q23)/G23 -> -0.01746114 | Y23: =VLOOKUP(C23,每日行情!A:D,4,FALSE) -> 64.7 | Z23: =VLOOKUP(C23,每日行情!A:E,5,FALSE) -> 1.4 | AA23: =IF(I23="",((TODAY()-A23)*G23)/365.24,((I23-A23)*G23)/365.24) -> 1690.9429 | AB23: 強勢股 | AC23: 破10日線，認賠出場
A24: 45737 | C24: 2634 | D24: =VLOOKUP(C24,每日行情!A:B,2,FALSE) -> 漢翔 | E24: 1000 | F24: 51.7 | G24: =E24*F24 -> 51700 | H24: 44 | I24: 45743 | J24: 52.5 | K24: =E24*J24 -> 52500 | L24: 44 | M24: 157 | N24: 0 | O24: =IF(I24="",E24*Y24,0) -> 0 | P24: =IF(I24="",R24-H24,(K24-H24-SUM(L24:N24)+R24-S24-T24)-G24)+(ROUND(R24*V24,0)-ROUND(R24*(1+V24),0)*W24) -> 545 | Q24: =IF(I24="",(O24-G24-(O24*0.1425%*0.65)-(O24*0.3%)-S24-T24),0) -> 0 | S24: 10 | U24: =(V24*50%)/(1+50%*V24) -> 0 | W24: 0.11 | X24: =(P24+Q24)/G24 -> 0.010541586 | Y24: =VLOOKUP(C24,每日行情!A:D,4,FALSE) -> 62.1 | Z24: =VLOOKUP(C24,每日行情!A:E,5,FALSE) -> 1.4 | AA24: =IF(I24="",((TODAY()-A24)*G24)/365.24,((I24-A24)*G24)/365.24) -> 849.30457 | AB24: 強勢股 | AC24: 破10日線，獲利了結
A25: 45740 | C25: 3035 | D25: =VLOOKUP(C25,每日行情!A:B,2,FALSE) -> 智原 | E25: 1000 | F25: 249 | G25: =E25*F25 -> 249000 | H25: 212 | I25: 45743 | J25: 242 | K25: =E25*J25 -> 242000 | L25: 206 | M25: 726 | N25: 0 | O25: =IF(I25="",E25*Y25,0) -> 0 | P25: =IF(I25="",R25-H25,(K25-H25-SUM(L25:N25)+R25-S25-T25)-G25)+(ROUND(R25*V25,0)-ROUND(R25*(1+V25),0)*W25) -> -8154 | Q25: =IF(I25="",(O25-G25-(O25*0.1425%*0.65)-(O25*0.3%)-S25-T25),0) -> 0 | S25: 10 | U25: =(V25*50%)/(1+50%*V25) -> 0 | W25: 0.11 | X25: =(P25+Q25)/G25 -> -0.032746988 | Y25: =VLOOKUP(C25,每日行情!A:D,4,FALSE) -> 197.5 | Z25: =VLOOKUP(C25,每日行情!A:E,5,FALSE) -> 0 | AA25: =IF(I25="",((TODAY()-A25)*G25)/365.24,((I25-A25)*G25)/365.24) -> 2045.2305 | AB25: 強勢股 | AC25: 破10日線，認賠出場
A26: 45740 | C26: 5534 | D26: =VLOOKUP(C26,每日行情!A:B,2,FALSE) -> 長虹 | E26: 1000 | F26: 108 | G26: =E26*F26 -> 108000 | H26: 92 | I26: 45743 | J26: 105.5 | K26: =E26*J26 -> 105500 | L26: 90 | M26: 316 | N26: 0 | O26: =IF(I26="",E26*Y26,0) -> 0 | P26: =IF(I26="",R26-H26,(K26-H26-SUM(L26:N26)+R26-S26-T26)-G26)+(ROUND(R26*V26,0)-ROUND(R26*(1+V26),0)*W26) -> -3008 | Q26: =IF(I26="",(O26-G26-(O26*0.1425%*0.65)-(O26*0.3%)-S26-T26),0) -> 0 | S26: 10 | U26: =(V26*50%)/(1+50%*V26) -> 0 | W26: 0.11 | X26: =(P26+Q26)/G26 -> -0.027851852 | Y26: =VLOOKUP(C26,每日行情!A:D,4,FALSE) -> 70.3 | Z26: =VLOOKUP(C26,每日行情!A:E,5,FALSE) -> -0.5 | AA26: =IF(I26="",((TODAY()-A26)*G26)/365.24,((I26-A26)*G26)/365.24) -> 887.08794 | AB26: 強勢股 | AC26: 破10日線，認賠出場
A27: 45910 | C27: 1711 | D27: =VLOOKUP(C27,每日行情!A:B,2,FALSE) -> 永光 | E27: 3000 | F27: 20.3 | G27: =E27*F27 -> 60900 | H27: 52 | I27: 45924 | J27: 19.65 | K27: =E27*J27 -> 58950 | L27: 50 | M27: 176 | N27: 0 | O27: =IF(I27="",E27*Y27,0) -> 0 | P27: =IF(I27="",R27-H27,(K27-H27-SUM(L27:N27)+R27-S27-T27)-G27)+(ROUND(R27*V27,0)-ROUND(R27*(1+V27),0)*W27) -> -2228 | Q27: =IF(I27="",(O27-G27-(O27*0.1425%*0.65)-(O27*0.3%)-S27-T27),0) -> 0 | U27: =(V27*50%)/(1+50%*V27) -> 0 | W27: 0.11 | X27: =(P27+Q27)/G27 -> -0.036584565 | Y27: =VLOOKUP(C27,每日行情!A:D,4,FALSE) -> 44.45 | Z27: =VLOOKUP(C27,每日行情!A:E,5,FALSE) -> 1.35 | AA27: =IF(I27="",((TODAY()-A27)*G27)/365.24,((I27-A27)*G27)/365.24) -> 2334.3555 | AB27: 阿水一式 | AC27: 破5日線，認賠出場
A28: 45917 | C28: 3006 | D28: =VLOOKUP(C28,每日行情!A:B,2,FALSE) -> 晶豪科 | E28: 1000 | F28: 65.4 | G28: =E28*F28 -> 65400 | H28: 55 | I28: 45925 | J28: 72.5 | K28: =E28*J28 -> 72500 | L28: 61 | M28: 217 | N28: 0 | O28: =IF(I28="",E28*Y28,0) -> 0 | P28: =IF(I28="",R28-H28,(K28-H28-SUM(L28:N28)+R28-S28-T28)-G28)+(ROUND(R28*V28,0)-ROUND(R28*(1+V28),0)*W28) -> 6767 | Q28: =IF(I28="",(O28-G28-(O28*0.1425%*0.65)-(O28*0.3%)-S28-T28),0) -> 0 | U28: =(V28*50%)/(1+50%*V28) -> 0 | W28: 0.11 | X28: =(P28+Q28)/G28 -> 0.10347095 | Y28: =VLOOKUP(C28,每日行情!A:D,4,FALSE) -> 244.5 | Z28: =VLOOKUP(C28,每日行情!A:E,5,FALSE) -> 15.5 | AA28: =IF(I28="",((TODAY()-A28)*G28)/365.24,((I28-A28)*G28)/365.24) -> 1432.4828 | AB28: 阿水一式 | AC28: 破5日線，獲利了結
A29: 45917 | C29: 3042 | D29: =VLOOKUP(C29,每日行情!A:B,2,FALSE) -> 晶技 | E29: 1000 | F29: 92.8 | G29: =E29*F29 -> 92800 | H29: 79 | I29: 45925 | J29: 91.4 | K29: =E29*J29 -> 91400 | L29: 78 | M29: 274 | N29: 0 | O29: =IF(I29="",E29*Y29,0) -> 0 | P29: =IF(I29="",R29-H29,(K29-H29-SUM(L29:N29)+R29-S29-T29)-G29)+(ROUND(R29*V29,0)-ROUND(R29*(1+V29),0)*W29) -> -1831 | Q29: =IF(I29="",(O29-G29-(O29*0.1425%*0.65)-(O29*0.3%)-S29-T29),0) -> 0 | U29: =(V29*50%)/(1+50%*V29) -> 0 | W29: 0.11 | X29: =(P29+Q29)/G29 -> -0.019730603 | Y29: =VLOOKUP(C29,每日行情!A:D,4,FALSE) -> 188 | Z29: =VLOOKUP(C29,每日行情!A:E,5,FALSE) -> -1.5 | AA29: =IF(I29="",((TODAY()-A29)*G29)/365.24,((I29-A29)*G29)/365.24) -> 2032.6361 | AB29: 阿水一式 | AC29: 破5日線，認賠出場
A30: 45917 | C30: 3532 | D30: =VLOOKUP(C30,每日行情!A:B,2,FALSE) -> 台勝科 | E30: 1000 | F30: 95 | G30: =E30*F30 -> 95000 | H30: 81 | I30: 45925 | J30: 106.5 | K30: =E30*J30 -> 106500 | L30: 91 | M30: 319 | N30: 0 | O30: =IF(I30="",E30*Y30,0) -> 0 | P30: =IF(I30="",R30-H30,(K30-H30-SUM(L30:N30)+R30-S30-T30)-G30)+(ROUND(R30*V30,0)-ROUND(R30*(1+V30),0)*W30) -> 11009 | Q30: =IF(I30="",(O30-G30-(O30*0.1425%*0.65)-(O30*0.3%)-S30-T30),0) -> 0 | U30: =(V30*50%)/(1+50%*V30) -> 0 | W30: 0.11 | X30: =(P30+Q30)/G30 -> 0.11588421 | Y30: =VLOOKUP(C30,每日行情!A:D,4,FALSE) -> 417.5 | Z30: =VLOOKUP(C30,每日行情!A:E,5,FALSE) -> 17.5 | AA30: =IF(I30="",((TODAY()-A30)*G30)/365.24,((I30-A30)*G30)/365.24) -> 2080.8236 | AB30: 阿水一式 | AC30: 破5日線，獲利了結
A31: 45925 | C31: 2324 | D31: =VLOOKUP(C31,每日行情!A:B,2,FALSE) -> 仁寶 | E31: 2000 | F31: 37.1 | G31: =E31*F31 -> 74200 | H31: 63 | I31: 45930 | J31: 32.4 | K31: =E31*J31 -> 64800 | L31: 55 | M31: 194 | N31: 0 | O31: =IF(I31="",E31*Y31,0) -> 0 | P31: =IF(I31="",R31-H31,(K31-H31-SUM(L31:N31)+R31-S31-T31)-G31)+(ROUND(R31*V31,0)-ROUND(R31*(1+V31),0)*W31) -> -9712 | Q31: =IF(I31="",(O31-G31-(O31*0.1425%*0.65)-(O31*0.3%)-S31-T31),0) -> 0 | U31: =(V31*50%)/(1+50%*V31) -> 0 | W31: 0.11 | X31: =(P31+Q31)/G31 -> -0.13088949 | Y31: =VLOOKUP(C31,每日行情!A:D,4,FALSE) -> 36.7 | Z31: =VLOOKUP(C31,每日行情!A:E,5,FALSE) -> 0.7 | AA31: =IF(I31="",((TODAY()-A31)*G31)/365.24,((I31-A31)*G31)/365.24) -> 1015.7705 | AB31: 阿水一式 | AC31: 破10日線，認賠出場
A32: 45925 | C32: 6548 | D32: =VLOOKUP(C32,每日行情!A:B,2,FALSE) -> 長科* | E32: 2000 | F32: 35.35 | G32: =E32*F32 -> 70700 | H32: 60 | I32: 45933 | J32: 36 | K32: =E32*J32 -> 72000 | L32: 61 | M32: 216 | N32: 0 | O32: =IF(I32="",E32*Y32,0) -> 0 | P32: =IF(I32="",R32-H32,(K32-H32-SUM(L32:N32)+R32-S32-T32)-G32)+(ROUND(R32*V32,0)-ROUND(R32*(1+V32),0)*W32) -> 963 | Q32: =IF(I32="",(O32-G32-(O32*0.1425%*0.65)-(O32*0.3%)-S32-T32),0) -> 0 | U32: =(V32*50%)/(1+50%*V32) -> 0 | W32: 0.11 | X32: =(P32+Q32)/G32 -> 0.013620934 | Y32: =VLOOKUP(C32,每日行情!A:D,4,FALSE) -> 83.4 | Z32: =VLOOKUP(C32,每日行情!A:E,5,FALSE) -> 1.2 | AA32: =IF(I32="",((TODAY()-A32)*G32)/365.24,((I32-A32)*G32)/365.24) -> 1548.5708 | AB32: 阿水一式 | AC32: 破5日線，獲利了結
A33: 45925 | C33: 2375 | D33: =VLOOKUP(C33,每日行情!A:B,2,FALSE) -> 凱美 | E33: 1000 | F33: 78.8 | G33: =E33*F33 -> 78800 | H33: 67 | I33: 45944 | J33: 76.8 | K33: =E33*J33 -> 76800 | L33: 65 | M33: 230 | N33: 0 | O33: =IF(I33="",E33*Y33,0) -> 0 | P33: =IF(I33="",R33-H33,(K33-H33-SUM(L33:N33)+R33-S33-T33)-G33)+(ROUND(R33*V33,0)-ROUND(R33*(1+V33),0)*W33) -> -2362 | Q33: =IF(I33="",(O33-G33-(O33*0.1425%*0.65)-(O33*0.3%)-S33-T33),0) -> 0 | U33: =(V33*50%)/(1+50%*V33) -> 0 | W33: 0.11 | X33: =(P33+Q33)/G33 -> -0.029974619 | Y33: =VLOOKUP(C33,每日行情!A:D,4,FALSE) -> 125.5 | Z33: =VLOOKUP(C33,每日行情!A:E,5,FALSE) -> -5.5 | AA33: =IF(I33="",((TODAY()-A33)*G33)/365.24,((I33-A33)*G33)/365.24) -> 4099.2224 | AB33: 阿水一式 | AC33: 破10日線，認賠出場
A34: 45925 | C34: 3628 | D34: =VLOOKUP(C34,每日行情!A:B,2,FALSE) -> 盈正 | E34: 1000 | F34: 59.1 | G34: =E34*F34 -> 59100 | H34: 50 | I34: 45939 | J34: 73.5 | K34: =E34*J34 -> 73500 | L34: 62 | M34: 220 | N34: 0 | O34: =IF(I34="",E34*Y34,0) -> 0 | P34: =IF(I34="",R34-H34,(K34-H34-SUM(L34:N34)+R34-S34-T34)-G34)+(ROUND(R34*V34,0)-ROUND(R34*(1+V34),0)*W34) -> 14068 | Q34: =IF(I34="",(O34-G34-(O34*0.1425%*0.65)-(O34*0.3%)-S34-T34),0) -> 0 | U34: =(V34*50%)/(1+50%*V34) -> 0 | W34: 0.11 | X34: =(P34+Q34)/G34 -> 0.23803723 | Y34: =VLOOKUP(C34,每日行情!A:D,4,FALSE) -> 71.5 | Z34: =VLOOKUP(C34,每日行情!A:E,5,FALSE) -> 1.4 | AA34: =IF(I34="",((TODAY()-A34)*G34)/365.24,((I34-A34)*G34)/365.24) -> 2265.3598 | AB34: 阿水一式 | AC34: 破5日線，獲利了結
A35: 45889 | C35: 3661 | D35: =VLOOKUP(C35,每日行情!A:B,2,FALSE) -> 世芯-KY | E35: 10 | F35: 3760 | G35: =E35*F35 -> 37600 | H35: 32 | I35: 45964 | J35: 3460 | K35: =E35*J35 -> 34600 | L35: 30 | M35: 104 | N35: 0 | O35: =IF(I35="",E35*Y35,0) -> 0 | P35: =IF(I35="",R35-H35,(K35-H35-SUM(L35:N35)+R35-S35-T35)-G35)+(ROUND(R35*V35,0)-ROUND(R35*(1+V35),0)*W35) -> -2852.04 | Q35: =IF(I35="",(O35-G35-(O35*0.1425%*0.65)-(O35*0.3%)-S35-T35),0) -> 0 | R35: 364 | S35: 10 | U35: =(V35*50%)/(1+50%*V35) -> 0 | W35: 0.11 | X35: =(P35+Q35)/G35 -> -0.075852128 | Y35: =VLOOKUP(C35,每日行情!A:D,4,FALSE) -> 3685 | Z35: =VLOOKUP(C35,每日行情!A:E,5,FALSE) -> -20 | AA35: =IF(I35="",((TODAY()-A35)*G35)/365.24,((I35-A35)*G35)/365.24) -> 7720.9506 | AB35: 存股 | AC35: 破5日線，認賠出場
A36: 45924 | C36: 3661 | D36: =VLOOKUP(C36,每日行情!A:B,2,FALSE) -> 世芯-KY | E36: 10 | F36: 3420 | G36: =E36*F36 -> 34200 | H36: 29 | I36: 45964 | J36: 3460 | K36: =E36*J36 -> 34600 | L36: 30 | M36: 104 | N36: 0 | O36: =IF(I36="",E36*Y36,0) -> 0 | P36: =IF(I36="",R36-H36,(K36-H36-SUM(L36:N36)+R36-S36-T36)-G36)+(ROUND(R36*V36,0)-ROUND(R36*(1+V36),0)*W36) -> 237 | Q36: =IF(I36="",(O36-G36-(O36*0.1425%*0.65)-(O36*0.3%)-S36-T36),0) -> 0 | U36: =(V36*50%)/(1+50%*V36) -> 0 | W36: 0.11 | X36: =(P36+Q36)/G36 -> 0.0069298246 | Y36: =VLOOKUP(C36,每日行情!A:D,4,FALSE) -> 3685 | Z36: =VLOOKUP(C36,每日行情!A:E,5,FALSE) -> -20 | AA36: =IF(I36="",((TODAY()-A36)*G36)/365.24,((I36-A36)*G36)/365.24) -> 3745.4824 | AB36: 存股 | AC36: 破5日線，獲利了結
A37: 45926 | C37: 3661 | D37: =VLOOKUP(C37,每日行情!A:B,2,FALSE) -> 世芯-KY | E37: 10 | F37: 3260 | G37: =E37*F37 -> 32600 | H37: 27 | I37: 45964 | J37: 3460 | K37: =E37*J37 -> 34600 | L37: 29 | M37: 104 | N37: 0 | O37: =IF(I37="",E37*Y37,0) -> 0 | P37: =IF(I37="",R37-H37,(K37-H37-SUM(L37:N37)+R37-S37-T37)-G37)+(ROUND(R37*V37,0)-ROUND(R37*(1+V37),0)*W37) -> 1840 | Q37: =IF(I37="",(O37-G37-(O37*0.1425%*0.65)-(O37*0.3%)-S37-T37),0) -> 0 | U37: =(V37*50%)/(1+50%*V37) -> 0 | W37: 0.11 | X37: =(P37+Q37)/G37 -> 0.056441718 | Y37: =VLOOKUP(C37,每日行情!A:D,4,FALSE) -> 3685 | Z37: =VLOOKUP(C37,每日行情!A:E,5,FALSE) -> -20 | AA37: =IF(I37="",((TODAY()-A37)*G37)/365.24,((I37-A37)*G37)/365.24) -> 3391.7424 | AB37: 存股 | AC37: 破5日線，獲利了結
